Workbook

Sheet Input-Unit
C2: Unit economics of the project | F2: Made by | G2: https://feofinance.com/
C4: Input parameters
B6: 1. | C6: Cells that can be changed | D6: ххх
B7: 2. | C7: Cells that can't be changed (they contain a formula) | D7: =D6 -> ххх
B9: 3. | C9: Name of the project | D9: StepUP
B12: 1. | C12: Number of customers (subscribers) and conversions
B14: № | C14: Name | D14: Value | E14: Unit. | H14: SDR Velocity
B15: 1. | C15: Number of visits (clicks) (UA) | D15: 1000 | E15: units/month | H15: Working hours | I15: 8
B16: 2. | C16: Conversion to Registration (C1) | D16: 0.08 | E16: % | H16: Days | I16: 20
B17: 3. | C17: Total number of registrations (leads) | D17: =D15*D16 -> 80 | E17: units/month | H17: Call duration hours | I17: 0.5
B18: 4. | C18: Conversion from registration to payment (C2) | D18: 0.3 | E18: % | H18: Schedule fullfillment | I18: 0.8
B19: 5. | C19: Total number of paying users (B) | D19: =D18*D17 -> 24 | E19: units/month | H19: Calls done /month | I19: =I15*I16*I17*I18 -> 64
B20: 6. | C20: Final conversion from click to purchase (C3) | D20: =D16*D18 -> 0.024 | E20: % | H20: SDR HC | I20: =D17/I19 -> 1.25
B23: 2. | C23: Lifetime value (LTV)
G24: Смотрим модель с вариантами ARPPU
B25: № | C25: Name | D25: =D14 -> Value | E25: =E14 -> Unit. | G25: 200 | H25: 1
B26: 1. | C26: Average revenue per paying customer (ARPPU) | D26: 400 | E26: $ / month | G26: 400 | H26: 2
B27: 2. | C27: Customer Lifetime (CL) | D27: 27 | E27: months | G27: 1500 | H27: 3
B28: 3. | C28: Lifetime value (LTV) | D28: =sum('Results-Unit'!D35:O35)*D26/D19 -> 3822.2222 | E28: $
B29: 4. | C29: Churn rate | D29: =1/D27 -> 0.037037037 | E29: %
B32: 3. | C32: Customer Acquisition Cost (CAC)
B34: 3.1. | C34: Advertising costs
B36: =B$25 -> № | C36: =C$25 -> Name | D36: =D$25 -> Value | E36: =E$25 -> Unit.
B37: 1. | C37: Cost of 1 visit (click) | D37: 5 | E37: $
B38: 2. | C38: Number of visits (clicks) | D38: =$D$15 -> 1000 | E38: $ / unit
C39: Total advertising expenses | D39: =D37*D38 -> 5000 | E39: $ / month
B42: 3.2. | C42: Salary (not all staff, but only for marketing and advertising departments)
B44: =B$25 -> № | C44: =C$25 -> Name | D44: =D$25 -> Value | E44: =E$25 -> Unit.
B45: 1. | C45: Sales Development Representative | D45: =F45*I20 -> 2500 | E45: $ / month | F45: 2000
B46: 2. | C46: Product Manager | D46: 3000 | E46: $ / month
B47: 3. | C47: Founder | D47: 3000 | E47: $ / month
B48: 4. | E48: $ / month
B49: 5. | E49: $ / month
B50: 6. | E50: $ / month
B51: 7. | E51: $ / month
B52: 8. | E52: $ / month
B53: 9. | E53: $ / month
B54: 10. | E54: $ / month
C55: Total salary | D55: =SUM(D45:D54) -> 8500 | E55: $ / month
B58: 3.3. | C58: Other marketing and advertising expenses
...

Sheet Results-Unit
D2: Unit-econimics — Results | L2: Made by | M2: https://feofinance.com/
D3: ='Input-Unit'!D9 -> StepUP
C6: 1. | D6: Number of clients and conversions
C8: № | D8: =D20 -> Name | H8: =H20 -> Value | I8: =I20 -> Unit.
C9: 1. | D9: ='Input-Unit'!C15 -> Number of visits (clicks) (UA) | H9: ='Input-Unit'!D15 -> 1000 | I9: ='Input-Unit'!E15 -> units/month | J9: =D9 -> Number of visits (clicks) (UA) | K9: =H9 -> 1000
C10: 2. | D10: ='Input-Unit'!C16 -> Conversion to Registration (C1) | H10: ='Input-Unit'!D16 -> 0.08 | I10: ='Input-Unit'!E16 -> % | J10: =D11 -> Total number of registrations (leads) | K10: =H11 -> 80
C11: 3. | D11: ='Input-Unit'!C17 -> Total number of registrations (leads) | H11: ='Input-Unit'!D17 -> 80 | I11: ='Input-Unit'!E17 -> units/month | J11: =D13 -> Total number of paying users (B) | K11: =H13 -> 24
C12: 4. | D12: ='Input-Unit'!C18 -> Conversion from registration to payment (C2) | H12: ='Input-Unit'!D18 -> 0.3 | I12: ='Input-Unit'!E18 -> %
C13: 5. | D13: ='Input-Unit'!C19 -> Total number of paying users (B) | H13: ='Input-Unit'!D19 -> 24 | I13: ='Input-Unit'!E19 -> units/month
C14: 6. | D14: ='Input-Unit'!C20 -> Final conversion from click to purchase (C3) | H14: ='Input-Unit'!D20 -> 0.024 | I14: ='Input-Unit'!E20 -> %
C15: 7. | D15: Churn rate | H15: ='Results-Unit'!H25 -> 0.037037037 | I15: %
C18: 2. | D18: The ratio of LTV to CAC
C20: № | D20: ='Input-Unit'!C36 -> Name | H20: ='Input-Unit'!D36 -> Value | I20: ='Input-Unit'!E36 -> Unit.
C21: 1. | D21: Customer Acquisition Cost (CAC) | H21: ='Input-Unit'!D74 -> 562.5 | I21: $ | J21: =D22 -> Lifetime value per customer (LTV) | K21: =H22 -> 3822.2222
C22: 2. | D22: Lifetime value per customer (LTV) | H22: ='Input-Unit'!D28 -> 3822.2222 | I22: $ | J22: =D21 -> Customer Acquisition Cost (CAC) | K22: =H21 -> 562.5
C23: 3. | D23: Difference between LTV and CAC (LTV – CAC) | H23: =H22-H21 -> 3259.7222 | I23: $ | J23: =D23 -> Difference between LTV and CAC (LTV – CAC) | K23: =H23 -> 3259.7222
C24: 4. | D24: LTV/CAC ratio | H24: =H22/H21 -> 6.7950617 | I24: k
C25: 5. | D25: Churn rate | H25: =1/'Input-Unit'!D27 -> 0.037037037 | I25: %
C29: 3. | D29: Cohort analysis | K29: =CONCATENATE("LTV / CAC = ",TEXT(H24,"# ##0.0")) -> LTV / CAC = 6.8
C31: Number of clients (new + old)
D33: Month
D34: 1 | E34: =D34+1 -> 2 | F34: =E34+1 -> 3 | G34: =F34+1 -> 4 | H34: =G34+1 -> 5 | I34: =H34+1 -> 6 | J34: =I34+1 -> 7 | K34: =J34+1 -> 8 | L34: =K34+1 -> 9 | ... O34: =N34+1 -> 12
A35: =$H$15 -> 0.037037037 | B35: Month | C35: 1 | D35: =$H$13 -> 24 | E35: =IF(D35-$D35*$H15<0,0,IF(ROUND(D35-$D35*$H15,2)=0,0,D35-$D35*$H15)) -> 23.111111 | F35: =IF(E35-$D35*$H15<0,0,IF(ROUND(E35-$D35*$H15,2)=0,0,E35-$D35*$H15)) -> 22.222222 | G35: =IF(F35-$D35*$H15<0,0,IF(ROUND(F35-$D35*$H15,2)=0,0,F35-$D35*$H15)) -> 21.333333 | H35: =IF(G35-$D35*$H15<0,0,IF(ROUND(G35-$D35*$H15,2)=0,0,G35-$D35*$H15)) -> 20.444444 | I35: =IF(H35-$D35*$H15<0,0,IF(ROUND(H35-$D35*$H15,2)=0,0,H35-$D35*$H15)) -> 19.555556 | J35: =IF(I35-$D35*$H15<0,0,IF(ROUND(I35-$D35*$H15,2)=0,0,I35-$D35*$H15)) -> 18.666667 | K35: =IF(J35-$D35*$H15<0,0,IF(ROUND(J35-$D35*$H15,2)=0,0,J35-$D35*$H15)) -> 17.777778 | L35: =IF(K35-$D35*$H15<0,0,IF(ROUND(K35-$D35*$H15,2)=0,0,K35-$D35*$H15)) -> 16.888889 | ... O35: =IF(N35-$D35*$H15<0,0,IF(ROUND(N35-$D35*$H15,2)=0,0,N35-$D35*$H15)) -> 14.222222
A36: =$H$15 -> 0.037037037 | C36: =C35+1 -> 2 | E36: =$H$13 -> 24 | F36: =IF(E36-$E36*$A36<0,0,IF(ROUND(E36-$E36*$A36,2)=0,0,E36-$E36*$A36)) -> 23.111111 | G36: =IF(F36-$E36*$A36<0,0,IF(ROUND(F36-$E36*$A36,2)=0,0,F36-$E36*$A36)) -> 22.222222 | H36: =IF(G36-$E36*$A36<0,0,IF(ROUND(G36-$E36*$A36,2)=0,0,G36-$E36*$A36)) -> 21.333333 | I36: =IF(H36-$E36*$A36<0,0,IF(ROUND(H36-$E36*$A36,2)=0,0,H36-$E36*$A36)) -> 20.444444 | J36: =IF(I36-$E36*$A36<0,0,IF(ROUND(I36-$E36*$A36,2)=0,0,I36-$E36*$A36)) -> 19.555556 | K36: =IF(J36-$E36*$A36<0,0,IF(ROUND(J36-$E36*$A36,2)=0,0,J36-$E36*$A36)) -> 18.666667 | L36: =IF(K36-$E36*$A36<0,0,IF(ROUND(K36-$E36*$A36,2)=0,0,K36-$E36*$A36)) -> 17.777778 | M36: =IF(L36-$E36*$A36<0,0,IF(ROUND(L36-$E36*$A36,2)=0,0,L36-$E36*$A36)) -> 16.888889 | ... O36: =IF(N36-$E36*$A36<0,0,IF(ROUND(N36-$E36*$A36,2)=0,0,N36-$E36*$A36)) -> 15.111111
A37: =$H$15 -> 0.037037037 | C37: =C36+1 -> 3 | F37: =$H$13 -> 24 | G37: =IF(F37-$F37*$A37<0,0,IF(ROUND(F37-$F37*$A37,2)=0,0,F37-$F37*$A37)) -> 23.111111 | H37: =IF(G37-$F37*$A37<0,0,IF(ROUND(G37-$F37*$A37,2)=0,0,G37-$F37*$A37)) -> 22.222222 | I37: =IF(H37-$F37*$A37<0,0,IF(ROUND(H37-$F37*$A37,2)=0,0,H37-$F37*$A37)) -> 21.333333 | J37: =IF(I37-$F37*$A37<0,0,IF(ROUND(I37-$F37*$A37,2)=0,0,I37-$F37*$A37)) -> 20.444444 | K37: =IF(J37-$F37*$A37<0,0,IF(ROUND(J37-$F37*$A37,2)=0,0,J37-$F37*$A37)) -> 19.555556 | L37: =IF(K37-$F37*$A37<0,0,IF(ROUND(K37-$F37*$A37,2)=0,0,K37-$F37*$A37)) -> 18.666667 | M37: =IF(L37-$F37*$A37<0,0,IF(ROUND(L37-$F37*$A37,2)=0,0,L37-$F37*$A37)) -> 17.777778 | N37: =IF(M37-$F37*$A37<0,0,IF(ROUND(M37-$F37*$A37,2)=0,0,M37-$F37*$A37)) -> 16.888889 | O37: =IF(N37-$F37*$A37<0,0,IF(ROUND(N37-$F37*$A37,2)=0,0,N37-$F37*$A37)) -> 16
A38: =$H$15 -> 0.037037037 | C38: =C37+1 -> 4 | G38: =$H$13 -> 24 | H38: =IF(G38-$G38*$A38<0,0,IF(ROUND(G38-$G38*$A38,2)=0,0,G38-$G38*$A38)) -> 23.111111 | I38: =IF(H38-$G38*$A38<0,0,IF(ROUND(H38-$G38*$A38,2)=0,0,H38-$G38*$A38)) -> 22.222222 | J38: =IF(I38-$G38*$A38<0,0,IF(ROUND(I38-$G38*$A38,2)=0,0,I38-$G38*$A38)) -> 21.333333 | K38: =IF(J38-$G38*$A38<0,0,IF(ROUND(J38-$G38*$A38,2)=0,0,J38-$G38*$A38)) -> 20.444444 | L38: =IF(K38-$G38*$A38<0,0,IF(ROUND(K38-$G38*$A38,2)=0,0,K38-$G38*$A38)) -> 19.555556 | M38: =IF(L38-$G38*$A38<0,0,IF(ROUND(L38-$G38*$A38,2)=0,0,L38-$G38*$A38)) -> 18.666667 | N38: =IF(M38-$G38*$A38<0,0,IF(ROUND(M38-$G38*$A38,2)=0,0,M38-$G38*$A38)) -> 17.777778 | O38: =IF(N38-$G38*$A38<0,0,IF(ROUND(N38-$G38*$A38,2)=0,0,N38-$G38*$A38)) -> 16.888889
A39: =$H$15 -> 0.037037037 | C39: =C38+1 -> 5 | H39: =$H$13 -> 24 | I39: =IF(H39-$H39*$A39<0,0,IF(ROUND(H39-$H39*$A39,2)=0,0,H39-$H39*$A39)) -> 23.111111 | J39: =IF(I39-$H39*$A39<0,0,IF(ROUND(I39-$H39*$A39,2)=0,0,I39-$H39*$A39)) -> 22.222222 | K39: =IF(J39-$H39*$A39<0,0,IF(ROUND(J39-$H39*$A39,2)=0,0,J39-$H39*$A39)) -> 21.333333 | L39: =IF(K39-$H39*$A39<0,0,IF(ROUND(K39-$H39*$A39,2)=0,0,K39-$H39*$A39)) -> 20.444444 | M39: =IF(L39-$H39*$A39<0,0,IF(ROUND(L39-$H39*$A39,2)=0,0,L39-$H39*$A39)) -> 19.555556 | N39: =IF(M39-$H39*$A39<0,0,IF(ROUND(M39-$H39*$A39,2)=0,0,M39-$H39*$A39)) -> 18.666667 | O39: =IF(N39-$H39*$A39<0,0,IF(ROUND(N39-$H39*$A39,2)=0,0,N39-$H39*$A39)) -> 17.777778
A40: =$H$15 -> 0.037037037 | C40: =C39+1 -> 6 | I40: =$H$13 -> 24 | J40: =IF(I40-$I40*$A40<0,0,IF(ROUND(I40-$I40*$A40,2)=0,0,I40-$I40*$A40)) -> 23.111111 | K40: =IF(J40-$I40*$A40<0,0,IF(ROUND(J40-$I40*$A40,2)=0,0,J40-$I40*$A40)) -> 22.222222 | L40: =IF(K40-$I40*$A40<0,0,IF(ROUND(K40-$I40*$A40,2)=0,0,K40-$I40*$A40)) -> 21.333333 | M40: =IF(L40-$I40*$A40<0,0,IF(ROUND(L40-$I40*$A40,2)=0,0,L40-$I40*$A40)) -> 20.444444 | N40: =IF(M40-$I40*$A40<0,0,IF(ROUND(M40-$I40*$A40,2)=0,0,M40-$I40*$A40)) -> 19.555556 | O40: =IF(N40-$I40*$A40<0,0,IF(ROUND(N40-$I40*$A40,2)=0,0,N40-$I40*$A40)) -> 18.666667
A41: =$H$15 -> 0.037037037 | C41: =C40+1 -> 7 | J41: =$H$13 -> 24 | K41: =IF(J41-$J41*$A41<0,0,IF(ROUND(J41-$J41*$A41,2)=0,0,J41-$J41*$A41)) -> 23.111111 | L41: =IF(K41-$J41*$A41<0,0,IF(ROUND(K41-$J41*$A41,2)=0,0,K41-$J41*$A41)) -> 22.222222 | M41: =IF(L41-$J41*$A41<0,0,IF(ROUND(L41-$J41*$A41,2)=0,0,L41-$J41*$A41)) -> 21.333333 | N41: =IF(M41-$J41*$A41<0,0,IF(ROUND(M41-$J41*$A41,2)=0,0,M41-$J41*$A41)) -> 20.444444 | O41: =IF(N41-$J41*$A41<0,0,IF(ROUND(N41-$J41*$A41,2)=0,0,N41-$J41*$A41)) -> 19.555556
A42: =$H$15 -> 0.037037037 | C42: =C41+1 -> 8 | K42: =$H$13 -> 24 | L42: =IF(K42-$K42*$A42<0,0,IF(ROUND(K42-$K42*$A42,2)=0,0,K42-$K42*$A42)) -> 23.111111 | M42: =IF(L42-$K42*$A42<0,0,IF(ROUND(L42-$K42*$A42,2)=0,0,L42-$K42*$A42)) -> 22.222222 | N42: =IF(M42-$K42*$A42<0,0,IF(ROUND(M42-$K42*$A42,2)=0,0,M42-$K42*$A42)) -> 21.333333 | O42: =IF(N42-$K42*$A42<0,0,IF(ROUND(N42-$K42*$A42,2)=0,0,N42-$K42*$A42)) -> 20.444444
A43: =$H$15 -> 0.037037037 | C43: =C42+1 -> 9 | L43: =$H$13 -> 24 | M43: =IF(L43-$L43*$A43<0,0,IF(ROUND(L43-$L43*$A43,2)=0,0,L43-$L43*$A43)) -> 23.111111 | N43: =IF(M43-$L43*$A43<0,0,IF(ROUND(M43-$L43*$A43,2)=0,0,M43-$L43*$A43)) -> 22.222222 | O43: =IF(N43-$L43*$A43<0,0,IF(ROUND(N43-$L43*$A43,2)=0,0,N43-$L43*$A43)) -> 21.333333
A44: =$H$15 -> 0.037037037 | C44: =C43+1 -> 10 | M44: =$H$13 -> 24 | N44: =IF(M44-$M44*$A44<0,0,IF(ROUND(M44-$M44*$A44,2)=0,0,M44-$M44*$A44)) -> 23.111111 | O44: =IF(N44-$M44*$A44<0,0,IF(ROUND(N44-$M44*$A44,2)=0,0,N44-$M44*$A44)) -> 22.222222
A45: =$H$15 -> 0.037037037 | C45: =C44+1 -> 11 | N45: =$H$13 -> 24 | O45: =IF(N45-$N45*$A45<0,0,IF(ROUND(N45-$N45*$A45,2)=0,0,N45-$N45*$A45)) -> 23.111111
A46: =$H$15 -> 0.037037037 | C46: =C45+1 -> 12 | O46: =$H$13 -> 24
C47: Total | D47: =SUM(D35:D46) -> 24 | E47: =SUM(E35:E46) -> 47.111111 | F47: =SUM(F35:F46) -> 69.333333 | G47: =SUM(G35:G46) -> 90.666667 | H47: =SUM(H35:H46) -> 111.11111 | I47: =SUM(I35:I46) -> 130.66667 | J47: =SUM(J35:J46) -> 149.33333 | K47: =SUM(K35:K46) -> 167.11111 | ... O47: =SUM(O35:O46) -> 229.33333
C48: New | D48: =$H$13 -> 24 | E48: =$H$13 -> 24 | F48: =$H$13 -> 24 | G48: =$H$13 -> 24 | H48: =$H$13 -> 24 | I48: =$H$13 -> 24 | J48: =$H$13 -> 24 | K48: =$H$13 -> 24 | ... O48: =$H$13 -> 24
C49: Churn | D49: =-(-D50) -> 0 | E49: =-(D47-E50) -> -0.88888889 | F49: =-(E47-F50) -> -1.7777778 | G49: =-(F47-G50) -> -2.6666667 | H49: =-(G47-H50) -> -3.5555556 | I49: =-(H47-I50) -> -4.4444444 | J49: =-(I47-J50) -> -5.3333333 | K49: =-(J47-K50) -> -6.2222222 | L49: =-(K47-L50) -> -7.1111111 | ... O49: =-(N47-O50) -> -9.7777778
C50: Old | D50: =D47-D48 -> 0 | E50: =E47-E48 -> 23.111111 | F50: =F47-F48 -> 45.333333 | G50: =G47-G48 -> 66.666667 | H50: =H47-H48 -> 87.111111 | I50: =I47-I48 -> 106.66667 | J50: =J47-J48 -> 125.33333 | K50: =K47-K48 -> 143.11111 | ... O50: =O47-O48 -> 205.33333
C54: 4. | D54: Cash flow by month
C56: Name | G56: 1 | H56: =G56+1 -> 2 | I56: =H56+1 -> 3 | J56: =I56+1 -> 4 | K56: =J56+1 -> 5 | L56: =K56+1 -> 6 | M56: =L56+1 -> 7 | N56: =M56+1 -> 8 | O56: =N56+1 -> 9 | ... R56: =Q56+1 -> 12
...

Sheet Input
A1: =BS!A1 -> Ok
C3: Financial Model — Input | G3: Made by | H3: https://feofinance.com/
C4: ='Input-Unit'!D9 -> StepUP
C6: v 1.0
C10: Input Parameters | D10: Go to Results
B12: I | C12: Settings
B14: 1. | C14: Cells that can be changed | D14: ххх
B15: 2. | C15: Cells that can't be changed (they contain a formula) | D15: =D14 -> ххх
B18: № | C18: Name | D18: Date
B19: 1. | C19: Model start date | D19: 46023
B20: 2. | C20: Model validity period, years | D20: =(D21-D19)/365.25 -> 6.9979466
B21: 3. | C21: Model end date | D21: =EOMONTH(CF!CN1,0) -> 48579
B25: II | C25: Capital Expenditures
B27: № | C27: Name | D27: Depreciation period, year | E27: Total, $ | F27: =CF!I1 -> 46023 | G27: =CF!J1 -> 46054 | H27: =CF!K1 -> 46082 | I27: =CF!L1 -> 46113 | J27: =CF!M1 -> 46143 | K27: =CF!N1 -> 46174 | L27: =CF!O1 -> 46204 | M27: =CF!P1 -> 46235 | ... CK27: =CF!CN1 -> 48549
B28: 1. | C28: Platform development | D28: 5 | E28: =SUM(F28:CK28) -> 20000 | F28: 5000 | G28: 5000 | H28: 5000 | I28: 5000 | J28: 0 | K28: 0 | L28: 0 | M28: 0 | N28: 0 | O28: 0 | P28: 0 | Q28: 0 | R28: 0 | S28: 0 | T28: 0 | U28: 0 | V28: 0 | W28: 0 | X28: 0 | Y28: 0 | Z28: 0 | AA28: 0 | AB28: 0 | AC28: 0 | AD28: 0 | AE28: 0 | AF28: 0 | AG28: 0 | AH28: 0 | AI28: 0 | AJ28: 0 | AK28: 0 | AL28: 0 | AM28: 0 | AN28: 0 | AO28: 0 | AP28: 0 | AQ28: 0 | AR28: 0 | AS28: 0 | AT28: 0 | AU28: 0 | AV28: 0 | AW28: 0 | AX28: 0 | AY28: 0 | AZ28: 0 | BA28: 0 | BB28: 0 | BC28: 0 | BD28: 0 | BE28: 0 | BF28: 0 | BG28: 0 | BH28: 0 | BI28: 0 | BJ28: 0 | BK28: 0 | BL28: 0 | BM28: 0 | BN28: 0 | BO28: 0 | BP28: 0 | BQ28: 0 | BR28: 0 | BS28: 0 | BT28: 0 | BU28: 0 | BV28: 0 | BW28: 0 | BX28: 0 | BY28: 0 | BZ28: 0 | CA28: 0 | CB28: 0 | CC28: 0 | CD28: 0 | CE28: 0 | CF28: 0 | CG28: 0 | CH28: 0 | CI28: 0 | CJ28: 0 | CK28: 0
B29: 2. | C29: Infrastructure setup | D29: 5 | E29: =SUM(F29:CK29) -> 4400 | H29: 0 | I29: 0 | J29: 4400 | K29: 0 | L29: 0 | M29: 0 | N29: 0 | O29: 0 | P29: 0 | Q29: 0 | R29: 0 | S29: 0 | T29: 0 | U29: 0 | V29: 0 | W29: 0 | X29: 0 | Y29: 0 | Z29: 0 | AA29: 0 | AB29: 0 | AC29: 0 | AD29: 0 | AE29: 0 | AF29: 0 | AG29: 0 | AH29: 0 | AI29: 0 | AJ29: 0 | AK29: 0 | AL29: 0 | AM29: 0 | AN29: 0 | AO29: 0 | AP29: 0 | AQ29: 0 | AR29: 0 | AS29: 0 | AT29: 0 | AU29: 0 | AV29: 0 | AW29: 0 | AX29: 0 | AY29: 0 | AZ29: 0 | BA29: 0 | BB29: 0 | BC29: 0 | BD29: 0 | BE29: 0 | BF29: 0 | BG29: 0 | BH29: 0 | BI29: 0 | BJ29: 0 | BK29: 0 | BL29: 0 | BM29: 0 | BN29: 0 | BO29: 0 | BP29: 0 | BQ29: 0 | BR29: 0 | BS29: 0 | BT29: 0 | BU29: 0 | BV29: 0 | BW29: 0 | BX29: 0 | BY29: 0 | BZ29: 0 | CA29: 0 | CB29: 0 | CC29: 0 | CD29: 0 | CE29: 0 | CF29: 0 | CG29: 0 | CH29: 0 | CI29: 0 | CJ29: 0 | CK29: 0
B30: 3. | D30: 5 | H30: 0 | I30: 0 | J30: 0 | K30: 0 | L30: 0 | M30: 0 | N30: 0 | O30: 0 | P30: 0 | Q30: 0 | R30: 0 | S30: 0 | T30: 0 | U30: 0 | V30: 0 | W30: 0 | X30: 0 | Y30: 0 | Z30: 0 | AA30: 0 | AB30: 0 | AC30: 0 | AD30: 0 | AE30: 0 | AF30: 0 | AG30: 0 | AH30: 0 | AI30: 0 | AJ30: 0 | AK30: 0 | AL30: 0 | AM30: 0 | AN30: 0 | AO30: 0 | AP30: 0 | AQ30: 0 | AR30: 0 | AS30: 0 | AT30: 0 | AU30: 0 | AV30: 0 | AW30: 0 | AX30: 0 | AY30: 0 | AZ30: 0 | BA30: 0 | BB30: 0 | BC30: 0 | BD30: 0 | BE30: 0 | BF30: 0 | BG30: 0 | BH30: 0 | BI30: 0 | BJ30: 0 | BK30: 0 | BL30: 0 | BM30: 0 | BN30: 0 | BO30: 0 | BP30: 0 | BQ30: 0 | BR30: 0 | BS30: 0 | BT30: 0 | BU30: 0 | BV30: 0 | BW30: 0 | BX30: 0 | BY30: 0 | BZ30: 0 | CA30: 0 | CB30: 0 | CC30: 0 | CD30: 0 | CE30: 0 | CF30: 0 | CG30: 0 | CH30: 0 | CI30: 0 | CJ30: 0 | CK30: 0
B31: 4. | D31: 5 | H31: 0 | I31: 0 | J31: 0 | K31: 0 | L31: 0 | M31: 0 | N31: 0 | O31: 0 | P31: 0 | Q31: 0 | R31: 0 | S31: 0 | T31: 0 | U31: 0 | V31: 0 | W31: 0 | X31: 0 | Y31: 0 | Z31: 0 | AA31: 0 | AB31: 0 | AC31: 0 | AD31: 0 | AE31: 0 | AF31: 0 | AG31: 0 | AH31: 0 | AI31: 0 | AJ31: 0 | AK31: 0 | AL31: 0 | AM31: 0 | AN31: 0 | AO31: 0 | AP31: 0 | AQ31: 0 | AR31: 0 | AS31: 0 | AT31: 0 | AU31: 0 | AV31: 0 | AW31: 0 | AX31: 0 | AY31: 0 | AZ31: 0 | BA31: 0 | BB31: 0 | BC31: 0 | BD31: 0 | BE31: 0 | BF31: 0 | BG31: 0 | BH31: 0 | BI31: 0 | BJ31: 0 | BK31: 0 | BL31: 0 | BM31: 0 | BN31: 0 | BO31: 0 | BP31: 0 | BQ31: 0 | BR31: 0 | BS31: 0 | BT31: 0 | BU31: 0 | BV31: 0 | BW31: 0 | BX31: 0 | BY31: 0 | BZ31: 0 | CA31: 0 | CB31: 0 | CC31: 0 | CD31: 0 | CE31: 0 | CF31: 0 | CG31: 0 | CH31: 0 | CI31: 0 | CJ31: 0 | CK31: 0
B32: 5. | D32: 5 | E32: =SUM(F32:CK32) -> 0 | F32: 0 | G32: 0 | H32: 0 | I32: 0 | J32: 0 | K32: 0 | L32: 0 | M32: 0 | N32: 0 | O32: 0 | P32: 0 | Q32: 0 | R32: 0 | S32: 0 | T32: 0 | U32: 0 | V32: 0 | W32: 0 | X32: 0 | Y32: 0 | Z32: 0 | AA32: 0 | AB32: 0 | AC32: 0 | AD32: 0 | AE32: 0 | AF32: 0 | AG32: 0 | AH32: 0 | AI32: 0 | AJ32: 0 | AK32: 0 | AL32: 0 | AM32: 0 | AN32: 0 | AO32: 0 | AP32: 0 | AQ32: 0 | AR32: 0 | AS32: 0 | AT32: 0 | AU32: 0 | AV32: 0 | AW32: 0 | AX32: 0 | AY32: 0 | AZ32: 0 | BA32: 0 | BB32: 0 | BC32: 0 | BD32: 0 | BE32: 0 | BF32: 0 | BG32: 0 | BH32: 0 | BI32: 0 | BJ32: 0 | BK32: 0 | BL32: 0 | BM32: 0 | BN32: 0 | BO32: 0 | BP32: 0 | BQ32: 0 | BR32: 0 | BS32: 0 | BT32: 0 | BU32: 0 | BV32: 0 | BW32: 0 | BX32: 0 | BY32: 0 | BZ32: 0 | CA32: 0 | CB32: 0 | CC32: 0 | CD32: 0 | CE32: 0 | CF32: 0 | CG32: 0 | CH32: 0 | CI32: 0 | CJ32: 0 | CK32: 0
C33: Total | E33: =SUM(E28:E32) -> 24400 | F33: =SUM(F28:F32) -> 5000 | G33: =SUM(G28:G32) -> 5000 | H33: =SUM(H28:H32) -> 5000 | I33: =SUM(I28:I32) -> 5000 | J33: =SUM(J28:J32) -> 4400 | K33: =SUM(K28:K32) -> 0 | L33: =SUM(L28:L32) -> 0 | ... CK33: =SUM(CK28:CK32) -> 0
B37: III | C37: Sales volume and direct costs
B39: 1. | C39: Main settings | D39: See sheet "Input-Unit"
B40: 2. | C40: Sales start date | D40: 45413 | F40: =round((D40-D19)/30.5,0) -> -20
B43: IV | C43: Other Expenses
B45: 1 | C45: Salary (without marketing and sales)
B47: № | C47: Job title | D47: Salary, Gross, $ per year | E47: Salary, Gross, $ per month | F47: Employment date | G47: Date of dismissal
B48: 1. | C48: CEO | D48: 36000 | E48: =D48/12 -> 3000 | F48: 45292 | G48: =$D$21 -> 48579
B49: 2. | C49: CPO | D49: 36000 | E49: =D49/12 -> 3000 | F49: 45292 | G49: =$D$21 -> 48579
B50: 3. | C50: DevOps | D50: 13200 | E50: =D50/12 -> 1100 | F50: 46174 | G50: =$D$21 -> 48579
B51: 4. | C51: Senior Fullstack Engineer | D51: 42000 | E51: =D51/12 -> 3500 | F51: 45323 | G51: 31/12/2024
B52: 5.
B53: 6.
B54: 7.
B55: 8.
B56: 9.
B57: 10.
C58: Total | D58: =SUM(D48:D57) -> 127200 | E58: =SUM(E48:E57) -> 10600
B61: 2 | C61: Fixed Expenses
B63: № | C63: Name | D63: Value, $ per month | E63: Start date | F63: Expiration date
B64: 1. | C64: Servers | D64: 1200 | E64: 45294 | F64: =$D$21 -> 48579
...

Sheet Results
B1: =BS!A1 -> Ok
D2: Financial Model — Results | J2: Made by | K2: https://feofinance.com/
D3: ='Input-Unit'!D9 -> StepUP
D6: =G33 -> 162300 | F6: =G31 -> 64920 | I6: =Input!D99 -> 324600 | L6: =Input!D98 -> 0.2
D7: Investment size (total) | F7: Investment size (investor) | I7: =Input!C99 -> Company valuation | L7: Investor's share
D9: =G225 -> 1868791 | F9: =G231 -> 1.17074 | I9: =-G225/G226 -> 28.78606 | L9: =if(G234<1,CONCATENATE(TEXT(round(G234*12,0),"0")," months"),CONCATENATE(TEXT(G234,"0.0")," years")) -> 2.0 years
D10: Investor's profit | F10: IRR (investor) | I10: Investor's capital gain | L10: Payback period (investor)
C14: I | D14: Project Budget
C16: № | D16: Name | G16: Total, $
C17: =CF!B17 -> 1. | D17: =CF!C17 -> Platform development | G17: =-CF!F17 -> 20000
C18: =CF!B18 -> 2. | D18: =CF!C18 -> Infrastructure setup | G18: =-CF!F18 -> 4400
C19: =CF!B19 -> 3. | D19: =CF!C19 | G19: =-CF!F19 -> 0
C20: =CF!B20 -> 4. | D20: =CF!C20 | G20: =-CF!F20 -> 0
C21: =CF!B21 -> 5. | D21: =CF!C21 | G21: =-CF!F21 -> 0
C22: 6. | D22: Working capital (marketing, payroll and other expenses) | G22: =IF((CF!F66+CF!F69)-SUM(G17:G21)<0,0,(CF!F66+CF!F69)-SUM(G17:G21)) -> 137900
D23: Total | G23: =SUM(G17:G22) -> 162300
C27: II | D27: Sources of Financing
C29: № | D29: Name | G29: =G16 -> Total, $
C30: 1. | D30: =Input!E91 -> Founders' funds | G30: =CF!F66 -> 97380 | Q30: =D30 -> Founders' funds | R30: =G30 -> 97380
C31: 2. | D31: =Input!D91 -> Investor's funds | G31: =CF!F69 -> 64920 | Q31: =D31 -> Investor's funds | R31: =G31 -> 64920
C32: 3. | D32: Project profit | G32: =IF(G23-G30-G31<0,0,G23-G30-G31) -> 0
D33: Total | G33: =G31+G30+G32 -> 162300
C38: III | D38: Unit-Economics
H50: =CONCATENATE("LTV / CAC = ",TEXT('Results-Unit'!H24,"# ##0.0")) -> LTV / CAC = 6.8
C54: IV | D54: =CF!C13 -> Cash Flow Statement (CF) | P54: Факт
P55: План
C56: № | D56: Name | F56: Total, $ | G56: =YEAR(CF!I1) -> 2026 | H56: =G56+1 -> 2027 | I56: =H56+1 -> 2028 | J56: =I56+1 -> 2029 | K56: =J56+1 -> 2030 | L56: =K56+1 -> 2031 | M56: =L56+1 -> 2032 | P56: Факт - далее план
C58: =CF!B15 -> 1. | D58: =CF!C15 -> Investment Phase
D59: =CF!C17 -> Platform development | F59: =SUM(G59:M59) -> -20000 | G59: =SUMIFS(CF!17:17,CF!$3:$3,G$56) -> -20000 | H59: =SUMIFS(CF!17:17,CF!$3:$3,H$56) -> 0 | I59: =SUMIFS(CF!17:17,CF!$3:$3,I$56) -> 0 | J59: =SUMIFS(CF!17:17,CF!$3:$3,J$56) -> 0 | K59: =SUMIFS(CF!17:17,CF!$3:$3,K$56) -> 0 | L59: =SUMIFS(CF!17:17,CF!$3:$3,L$56) -> 0 | M59: =SUMIFS(CF!17:17,CF!$3:$3,M$56) -> 0
D60: =CF!C18 -> Infrastructure setup | F60: =SUM(G60:M60) -> -4400 | G60: =SUMIFS(CF!18:18,CF!$3:$3,G$56) -> -4400 | H60: =SUMIFS(CF!18:18,CF!$3:$3,H$56) -> 0 | I60: =SUMIFS(CF!18:18,CF!$3:$3,I$56) -> 0 | J60: =SUMIFS(CF!18:18,CF!$3:$3,J$56) -> 0 | K60: =SUMIFS(CF!18:18,CF!$3:$3,K$56) -> 0 | L60: =SUMIFS(CF!18:18,CF!$3:$3,L$56) -> 0 | M60: =SUMIFS(CF!18:18,CF!$3:$3,M$56) -> 0
D61: =CF!C19 | F61: =SUM(G61:M61) -> 0 | G61: =SUMIFS(CF!19:19,CF!$3:$3,G$56) -> 0 | H61: =SUMIFS(CF!19:19,CF!$3:$3,H$56) -> 0 | I61: =SUMIFS(CF!19:19,CF!$3:$3,I$56) -> 0 | J61: =SUMIFS(CF!19:19,CF!$3:$3,J$56) -> 0 | K61: =SUMIFS(CF!19:19,CF!$3:$3,K$56) -> 0 | L61: =SUMIFS(CF!19:19,CF!$3:$3,L$56) -> 0 | M61: =SUMIFS(CF!19:19,CF!$3:$3,M$56) -> 0
D62: =CF!C20 | F62: =SUM(G62:M62) -> 0 | G62: =SUMIFS(CF!20:20,CF!$3:$3,G$56) -> 0 | H62: =SUMIFS(CF!20:20,CF!$3:$3,H$56) -> 0 | I62: =SUMIFS(CF!20:20,CF!$3:$3,I$56) -> 0 | J62: =SUMIFS(CF!20:20,CF!$3:$3,J$56) -> 0 | K62: =SUMIFS(CF!20:20,CF!$3:$3,K$56) -> 0 | L62: =SUMIFS(CF!20:20,CF!$3:$3,L$56) -> 0 | M62: =SUMIFS(CF!20:20,CF!$3:$3,M$56) -> 0
D63: =CF!C21 | F63: =SUM(G63:M63) -> 0 | G63: =SUMIFS(CF!21:21,CF!$3:$3,G$56) -> 0 | H63: =SUMIFS(CF!21:21,CF!$3:$3,H$56) -> 0 | I63: =SUMIFS(CF!21:21,CF!$3:$3,I$56) -> 0 | J63: =SUMIFS(CF!21:21,CF!$3:$3,J$56) -> 0 | K63: =SUMIFS(CF!21:21,CF!$3:$3,K$56) -> 0 | L63: =SUMIFS(CF!21:21,CF!$3:$3,L$56) -> 0 | M63: =SUMIFS(CF!21:21,CF!$3:$3,M$56) -> 0
D64: =CF!C22 -> Total investment phase | F64: =SUM(F59:F63) -> -24400 | G64: =SUM(G59:G63) -> -24400 | H64: =SUM(H59:H63) -> 0 | I64: =SUM(I59:I63) -> 0 | J64: =SUM(J59:J63) -> 0 | K64: =SUM(K59:K63) -> 0 | L64: =SUM(L59:L63) -> 0 | M64: =SUM(M59:M63) -> 0
C67: =CF!B25 -> 2. | D67: =CF!C25 -> Operational Phase
C68: =CF!B27 -> 1. | D68: =CF!C27 -> Income | F68: =SUM(G68:M68) -> 7861922.9 | G68: =SUM(G69) -> 0 | H68: =SUM(H69) -> 1155840 | I68: =SUM(I69) -> 1213632 | J68: =SUM(J69) -> 1274313.6 | K68: =SUM(K69) -> 1338029.3 | L68: =SUM(L69) -> 1404930.7 | M68: =SUM(M69) -> 1475177.3
C69: =CF!B28 -> 1.1. | D69: =CF!C28 -> Income — StepUP | F69: =SUM(G69:M69) -> 7861922.9 | G69: =SUMIFS(CF!28:28,CF!$3:$3,G$56) -> 0 | H69: =SUMIFS(CF!28:28,CF!$3:$3,H$56) -> 1155840 | I69: =SUMIFS(CF!28:28,CF!$3:$3,I$56) -> 1213632 | J69: =SUMIFS(CF!28:28,CF!$3:$3,J$56) -> 1274313.6 | K69: =SUMIFS(CF!28:28,CF!$3:$3,K$56) -> 1338029.3 | L69: =SUMIFS(CF!28:28,CF!$3:$3,L$56) -> 1404930.7 | M69: =SUMIFS(CF!28:28,CF!$3:$3,M$56) -> 1475177.3
C70: =CF!B30 -> 2. | D70: =CF!C30 -> Direct costs (marketing and sales) | F70: =SUM(G70:M70) -> -1114153.3 | G70: =SUM(G71:G73) -> 0 | H70: =SUM(H71:H73) -> -163800 | I70: =SUM(I71:I73) -> -171990 | J70: =SUM(J71:J73) -> -180589.5 | K70: =SUM(K71:K73) -> -189618.98 | L70: =SUM(L71:L73) -> -199099.92 | M70: =SUM(M71:M73) -> -209054.92
C71: =CF!B31 -> 2.1. | D71: =CF!C31 -> Advertising and marketing expenses | F71: =SUM(G71:M71) -> -428520.51 | G71: =SUMIFS(CF!31:31,CF!$3:$3,G$56) -> 0 | H71: =SUMIFS(CF!31:31,CF!$3:$3,H$56) -> -63000 | I71: =SUMIFS(CF!31:31,CF!$3:$3,I$56) -> -66150 | J71: =SUMIFS(CF!31:31,CF!$3:$3,J$56) -> -69457.5 | K71: =SUMIFS(CF!31:31,CF!$3:$3,K$56) -> -72930.375 | L71: =SUMIFS(CF!31:31,CF!$3:$3,L$56) -> -76576.894 | M71: =SUMIFS(CF!31:31,CF!$3:$3,M$56) -> -80405.738
C72: =CF!B32 -> 2.2. | D72: =CF!C32 -> Salary (marketing and sales) | F72: =SUM(G72:M72) -> -685632.81 | G72: =SUMIFS(CF!32:32,CF!$3:$3,G$56) -> 0 | H72: =SUMIFS(CF!32:32,CF!$3:$3,H$56) -> -100800 | I72: =SUMIFS(CF!32:32,CF!$3:$3,I$56) -> -105840 | J72: =SUMIFS(CF!32:32,CF!$3:$3,J$56) -> -111132 | K72: =SUMIFS(CF!32:32,CF!$3:$3,K$56) -> -116688.6 | L72: =SUMIFS(CF!32:32,CF!$3:$3,L$56) -> -122523.03 | M72: =SUMIFS(CF!32:32,CF!$3:$3,M$56) -> -128649.18
...

Sheet CF
A1: =BS!A1 -> Ok | B1: № | C1: Name | E1: Share | F1: Total | G1: Unit | I1: =Input!D19 -> 46023 | J1: =EOMONTH(I1,0)+1 -> 46054 | K1: =EOMONTH(J1,0)+1 -> 46082 | L1: =EOMONTH(K1,0)+1 -> 46113 | M1: =EOMONTH(L1,0)+1 -> 46143 | N1: =EOMONTH(M1,0)+1 -> 46174 | O1: =EOMONTH(N1,0)+1 -> 46204 | P1: =EOMONTH(O1,0)+1 -> 46235 | Q1: =EOMONTH(P1,0)+1 -> 46266 | ... CN1: =EOMONTH(CM1,0)+1 -> 48549
C2: Sales volume, MAU | I2: =if(I5<13,sumifs('Results-Unit'!$58:$58,'Results-Unit'!$56:$56,I$4-Input!$F$40),max('Results-Unit'!$58:$58)) -> 0 | J2: =if(J5<13,sumifs('Results-Unit'!$58:$58,'Results-Unit'!$56:$56,J$4-Input!$F$40),max('Results-Unit'!$58:$58)) -> 0 | K2: =if(K5<13,sumifs('Results-Unit'!$58:$58,'Results-Unit'!$56:$56,K$4-Input!$F$40),max('Results-Unit'!$58:$58)) -> 0 | L2: =if(L5<13,sumifs('Results-Unit'!$58:$58,'Results-Unit'!$56:$56,L$4-Input!$F$40),max('Results-Unit'!$58:$58)) -> 0 | M2: =if(M5<13,sumifs('Results-Unit'!$58:$58,'Results-Unit'!$56:$56,M$4-Input!$F$40),max('Results-Unit'!$58:$58)) -> 0 | N2: =if(N5<13,sumifs('Results-Unit'!$58:$58,'Results-Unit'!$56:$56,N$4-Input!$F$40),max('Results-Unit'!$58:$58)) -> 0 | O2: =if(O5<13,sumifs('Results-Unit'!$58:$58,'Results-Unit'!$56:$56,O$4-Input!$F$40),max('Results-Unit'!$58:$58)) -> 0 | P2: =if(P5<13,sumifs('Results-Unit'!$58:$58,'Results-Unit'!$56:$56,P$4-Input!$F$40),max('Results-Unit'!$58:$58)) -> 0 | ... CN2: =if(CN5<13,sumifs('Results-Unit'!$58:$58,'Results-Unit'!$56:$56,CN$4-Input!$F$40),max('Results-Unit'!$58:$58)) -> 229.33333
C3: Year | I3: =YEAR(I1) -> 2026 | J3: =YEAR(J1) -> 2026 | K3: =YEAR(K1) -> 2026 | L3: =YEAR(L1) -> 2026 | M3: =YEAR(M1) -> 2026 | N3: =YEAR(N1) -> 2026 | O3: =YEAR(O1) -> 2026 | P3: =YEAR(P1) -> 2026 | ... CN3: =YEAR(CN1) -> 2032
C4: Month | I4: =MONTH(I1) -> 1 | J4: =MONTH(J1) -> 2 | K4: =MONTH(K1) -> 3 | L4: =MONTH(L1) -> 4 | M4: =MONTH(M1) -> 5 | N4: =MONTH(N1) -> 6 | O4: =MONTH(O1) -> 7 | P4: =MONTH(P1) -> 8 | ... CN4: =MONTH(CN1) -> 12
C5: Serial number of the period | I5: 1 | J5: =I5+1 -> 2 | K5: =J5+1 -> 3 | L5: =K5+1 -> 4 | M5: =L5+1 -> 5 | N5: =M5+1 -> 6 | O5: =N5+1 -> 7 | P5: =O5+1 -> 8 | Q5: =P5+1 -> 9 | ... CN5: =CM5+1 -> 84
C6: =Input!C122 -> Indexation of production prices | I6: =SUMIFS(Input!$L122:$R122,Input!$L$121:$R$121,I$3) -> 1 | J6: =SUMIFS(Input!$L122:$R122,Input!$L$121:$R$121,J$3) -> 1 | K6: =SUMIFS(Input!$L122:$R122,Input!$L$121:$R$121,K$3) -> 1 | L6: =SUMIFS(Input!$L122:$R122,Input!$L$121:$R$121,L$3) -> 1 | M6: =SUMIFS(Input!$L122:$R122,Input!$L$121:$R$121,M$3) -> 1 | N6: =SUMIFS(Input!$L122:$R122,Input!$L$121:$R$121,N$3) -> 1 | O6: =SUMIFS(Input!$L122:$R122,Input!$L$121:$R$121,O$3) -> 1 | P6: =SUMIFS(Input!$L122:$R122,Input!$L$121:$R$121,P$3) -> 1 | ... CN6: =SUMIFS(Input!$L122:$R122,Input!$L$121:$R$121,CN$3) -> 1.3400956
C7: =Input!C123 -> Payroll indexation | I7: =SUMIFS(Input!$L123:$R123,Input!$L$121:$R$121,I$3) -> 1 | J7: =SUMIFS(Input!$L123:$R123,Input!$L$121:$R$121,J$3) -> 1 | K7: =SUMIFS(Input!$L123:$R123,Input!$L$121:$R$121,K$3) -> 1 | L7: =SUMIFS(Input!$L123:$R123,Input!$L$121:$R$121,L$3) -> 1 | M7: =SUMIFS(Input!$L123:$R123,Input!$L$121:$R$121,M$3) -> 1 | N7: =SUMIFS(Input!$L123:$R123,Input!$L$121:$R$121,N$3) -> 1 | O7: =SUMIFS(Input!$L123:$R123,Input!$L$121:$R$121,O$3) -> 1 | P7: =SUMIFS(Input!$L123:$R123,Input!$L$121:$R$121,P$3) -> 1 | ... CN7: =SUMIFS(Input!$L123:$R123,Input!$L$121:$R$121,CN$3) -> 1.3400956
C8: =Input!C124 -> Indexation of other expenses | I8: =SUMIFS(Input!$L124:$R124,Input!$L$121:$R$121,I$3) -> 1 | J8: =SUMIFS(Input!$L124:$R124,Input!$L$121:$R$121,J$3) -> 1 | K8: =SUMIFS(Input!$L124:$R124,Input!$L$121:$R$121,K$3) -> 1 | L8: =SUMIFS(Input!$L124:$R124,Input!$L$121:$R$121,L$3) -> 1 | M8: =SUMIFS(Input!$L124:$R124,Input!$L$121:$R$121,M$3) -> 1 | N8: =SUMIFS(Input!$L124:$R124,Input!$L$121:$R$121,N$3) -> 1 | O8: =SUMIFS(Input!$L124:$R124,Input!$L$121:$R$121,O$3) -> 1 | P8: =SUMIFS(Input!$L124:$R124,Input!$L$121:$R$121,P$3) -> 1 | ... CN8: =SUMIFS(Input!$L124:$R124,Input!$L$121:$R$121,CN$3) -> 1.3400956
C9: =Input!C125 -> Sales price indexation | I9: =SUMIFS(Input!$L125:$R125,Input!$L$121:$R$121,I$3) -> 1 | J9: =SUMIFS(Input!$L125:$R125,Input!$L$121:$R$121,J$3) -> 1 | K9: =SUMIFS(Input!$L125:$R125,Input!$L$121:$R$121,K$3) -> 1 | L9: =SUMIFS(Input!$L125:$R125,Input!$L$121:$R$121,L$3) -> 1 | M9: =SUMIFS(Input!$L125:$R125,Input!$L$121:$R$121,M$3) -> 1 | N9: =SUMIFS(Input!$L125:$R125,Input!$L$121:$R$121,N$3) -> 1 | O9: =SUMIFS(Input!$L125:$R125,Input!$L$121:$R$121,O$3) -> 1 | P9: =SUMIFS(Input!$L125:$R125,Input!$L$121:$R$121,P$3) -> 1 | ... CN9: =SUMIFS(Input!$L125:$R125,Input!$L$121:$R$121,CN$3) -> 1.3400956
C13: Cash Flow Statement (CF)
B15: 1. | C15: Investment Phase
B17: =Other!B15 -> 1. | C17: =Other!C15 -> Platform development | E17: =IFERROR(F17/$F$22,0) -> 0.81967213 | F17: =SUM(I17:CN17) -> -20000 | G17: $ | I17: =Other!I15 -> -5000 | J17: =Other!J15 -> -5000 | K17: =Other!K15 -> -5000 | L17: =Other!L15 -> -5000 | M17: =Other!M15 -> 0 | N17: =Other!N15 -> 0 | O17: =Other!O15 -> 0 | P17: =Other!P15 -> 0 | ... CN17: =Other!CN15 -> 0
B18: =Other!B16 -> 2. | C18: =Other!C16 -> Infrastructure setup | E18: =IFERROR(F18/$F$22,0) -> 0.18032787 | F18: =SUM(I18:CN18) -> -4400 | G18: $ | I18: =Other!I16 -> 0 | J18: =Other!J16 -> 0 | K18: =Other!K16 -> 0 | L18: =Other!L16 -> 0 | M18: =Other!M16 -> -4400 | N18: =Other!N16 -> 0 | O18: =Other!O16 -> 0 | P18: =Other!P16 -> 0 | ... CN18: =Other!CN16 -> 0
B19: =Other!B17 -> 3. | C19: =Other!C17 | E19: =IFERROR(F19/$F$22,0) -> 0 | F19: =SUM(I19:CN19) -> 0 | G19: $ | I19: =Other!I17 -> 0 | J19: =Other!J17 -> 0 | K19: =Other!K17 -> 0 | L19: =Other!L17 -> 0 | M19: =Other!M17 -> 0 | N19: =Other!N17 -> 0 | O19: =Other!O17 -> 0 | P19: =Other!P17 -> 0 | ... CN19: =Other!CN17 -> 0
B20: =Other!B18 -> 4. | C20: =Other!C18 | E20: =IFERROR(F20/$F$22,0) -> 0 | F20: =SUM(I20:CN20) -> 0 | G20: $ | I20: =Other!I18 -> 0 | J20: =Other!J18 -> 0 | K20: =Other!K18 -> 0 | L20: =Other!L18 -> 0 | M20: =Other!M18 -> 0 | N20: =Other!N18 -> 0 | O20: =Other!O18 -> 0 | P20: =Other!P18 -> 0 | ... CN20: =Other!CN18 -> 0
B21: =Other!B19 -> 5. | C21: =Other!C19 | E21: =IFERROR(F21/$F$22,0) -> 0 | F21: =SUM(I21:CN21) -> 0 | G21: $ | I21: =Other!I19 -> 0 | J21: =Other!J19 -> 0 | K21: =Other!K19 -> 0 | L21: =Other!L19 -> 0 | M21: =Other!M19 -> 0 | N21: =Other!N19 -> 0 | O21: =Other!O19 -> 0 | P21: =Other!P19 -> 0 | ... CN21: =Other!CN19 -> 0
C22: Total investment phase | E22: =IFERROR(F22/$F$22,0) -> 1 | F22: =SUM(I22:CN22) -> -24400 | G22: $ | I22: =SUM(I17:I21) -> -5000 | J22: =SUM(J17:J21) -> -5000 | K22: =SUM(K17:K21) -> -5000 | L22: =SUM(L17:L21) -> -5000 | M22: =SUM(M17:M21) -> -4400 | N22: =SUM(N17:N21) -> 0 | O22: =SUM(O17:O21) -> 0 | P22: =SUM(P17:P21) -> 0 | ... CN22: =SUM(CN17:CN21) -> 0
B25: 2. | C25: Operational Phase
B27: 1. | C27: Income | E27: =IFERROR(F27/$F$27,0) -> 1 | F27: =SUM(I27:CN27) -> 7861922.9 | G27: $ | I27: =SUM(I28) -> 0 | J27: =SUM(J28) -> 0 | K27: =SUM(K28) -> 0 | L27: =SUM(L28) -> 0 | M27: =SUM(M28) -> 0 | N27: =SUM(N28) -> 0 | O27: =SUM(O28) -> 0 | P27: =SUM(P28) -> 0 | ... CN27: =SUM(CN28) -> 122931.44
B28: 1.1. | C28: =CONCATENATE("Income — ",'Input-Unit'!D9) -> Income — StepUP | E28: =IFERROR(F28/$F$27,0) -> 1 | F28: =SUM(I28:CN28) -> 7861922.9 | G28: $ | I28: =if(I5<13,sumifs('Results-Unit'!$57:$57,'Results-Unit'!$56:$56,I$4-Input!$F$40),max('Results-Unit'!$57:$57))*I9 -> 0 | J28: =if(J5<13,sumifs('Results-Unit'!$57:$57,'Results-Unit'!$56:$56,J$4-Input!$F$40),max('Results-Unit'!$57:$57))*J9 -> 0 | K28: =if(K5<13,sumifs('Results-Unit'!$57:$57,'Results-Unit'!$56:$56,K$4-Input!$F$40),max('Results-Unit'!$57:$57))*K9 -> 0 | L28: =if(L5<13,sumifs('Results-Unit'!$57:$57,'Results-Unit'!$56:$56,L$4-Input!$F$40),max('Results-Unit'!$57:$57))*L9 -> 0 | M28: =if(M5<13,sumifs('Results-Unit'!$57:$57,'Results-Unit'!$56:$56,M$4-Input!$F$40),max('Results-Unit'!$57:$57))*M9 -> 0 | N28: =if(N5<13,sumifs('Results-Unit'!$57:$57,'Results-Unit'!$56:$56,N$4-Input!$F$40),max('Results-Unit'!$57:$57))*N9 -> 0 | O28: =if(O5<13,sumifs('Results-Unit'!$57:$57,'Results-Unit'!$56:$56,O$4-Input!$F$40),max('Results-Unit'!$57:$57))*O9 -> 0 | P28: =if(P5<13,sumifs('Results-Unit'!$57:$57,'Results-Unit'!$56:$56,P$4-Input!$F$40),max('Results-Unit'!$57:$57))*P9 -> 0 | ... CN28: =if(CN5<13,sumifs('Results-Unit'!$57:$57,'Results-Unit'!$56:$56,CN$4-Input!$F$40),max('Results-Unit'!$57:$57))*CN9 -> 122931.44
B30: 2. | C30: Direct costs (marketing and sales) | E30: =IFERROR(F30/(CF!$F$30+$F$38+$F$49+$F$57+$F$35),0) -> 0.34015007 | F30: =SUM(I30:CN30) -> -1114153.3 | G30: $ | I30: =SUM(I31:I33) -> 0 | J30: =SUM(J31:J33) -> 0 | K30: =SUM(K31:K33) -> 0 | L30: =SUM(L31:L33) -> 0 | M30: =SUM(M31:M33) -> 0 | N30: =SUM(N31:N33) -> 0 | O30: =SUM(O31:O33) -> 0 | P30: =SUM(P31:P33) -> 0 | ... CN30: =SUM(CN31:CN33) -> -17421.243
B31: 2.1. | C31: ='Results-Unit'!C62 -> Advertising and marketing expenses | E31: =IFERROR(F31/(CF!$F$30+$F$38+$F$49+$F$57+$F$35),0) -> 0.13082695 | F31: =SUM(I31:CN31) -> -428520.51 | G31: $ | I31: =if(I5<13,sumifs('Results-Unit'!$62:$62,'Results-Unit'!$56:$56,I$4-Input!$F$40),'Results-Unit'!$R$62)*I$8 -> 0 | J31: =if(J5<13,sumifs('Results-Unit'!$62:$62,'Results-Unit'!$56:$56,J$4-Input!$F$40),'Results-Unit'!$R$62)*J$8 -> 0 | K31: =if(K5<13,sumifs('Results-Unit'!$62:$62,'Results-Unit'!$56:$56,K$4-Input!$F$40),'Results-Unit'!$R$62)*K$8 -> 0 | L31: =if(L5<13,sumifs('Results-Unit'!$62:$62,'Results-Unit'!$56:$56,L$4-Input!$F$40),'Results-Unit'!$R$62)*L$8 -> 0 | M31: =if(M5<13,sumifs('Results-Unit'!$62:$62,'Results-Unit'!$56:$56,M$4-Input!$F$40),'Results-Unit'!$R$62)*M$8 -> 0 | N31: =if(N5<13,sumifs('Results-Unit'!$62:$62,'Results-Unit'!$56:$56,N$4-Input!$F$40),'Results-Unit'!$R$62)*N$8 -> 0 | O31: =if(O5<13,sumifs('Results-Unit'!$62:$62,'Results-Unit'!$56:$56,O$4-Input!$F$40),'Results-Unit'!$R$62)*O$8 -> 0 | P31: =if(P5<13,sumifs('Results-Unit'!$62:$62,'Results-Unit'!$56:$56,P$4-Input!$F$40),'Results-Unit'!$R$62)*P$8 -> 0 | ... CN31: =if(CN5<13,sumifs('Results-Unit'!$62:$62,'Results-Unit'!$56:$56,CN$4-Input!$F$40),'Results-Unit'!$R$62)*CN$8 -> -6700.4782
B32: 2.2. | C32: ='Results-Unit'!C66&" (marketing and sales)" -> Salary (marketing and sales) | E32: =IFERROR(F32/(CF!$F$30+$F$38+$F$49+$F$57+$F$35),0) -> 0.20932312 | F32: =SUM(I32:CN32) -> -685632.81 | G32: $ | I32: =if(I5<13,sumifs('Results-Unit'!$66:$66,'Results-Unit'!$56:$56,I$4-Input!$F$40),'Results-Unit'!$R$66)*I$8 -> 0 | J32: =if(J5<13,sumifs('Results-Unit'!$66:$66,'Results-Unit'!$56:$56,J$4-Input!$F$40),'Results-Unit'!$R$66)*J$8 -> 0 | K32: =if(K5<13,sumifs('Results-Unit'!$66:$66,'Results-Unit'!$56:$56,K$4-Input!$F$40),'Results-Unit'!$R$66)*K$8 -> 0 | L32: =if(L5<13,sumifs('Results-Unit'!$66:$66,'Results-Unit'!$56:$56,L$4-Input!$F$40),'Results-Unit'!$R$66)*L$8 -> 0 | M32: =if(M5<13,sumifs('Results-Unit'!$66:$66,'Results-Unit'!$56:$56,M$4-Input!$F$40),'Results-Unit'!$R$66)*M$8 -> 0 | N32: =if(N5<13,sumifs('Results-Unit'!$66:$66,'Results-Unit'!$56:$56,N$4-Input!$F$40),'Results-Unit'!$R$66)*N$8 -> 0 | O32: =if(O5<13,sumifs('Results-Unit'!$66:$66,'Results-Unit'!$56:$56,O$4-Input!$F$40),'Results-Unit'!$R$66)*O$8 -> 0 | P32: =if(P5<13,sumifs('Results-Unit'!$66:$66,'Results-Unit'!$56:$56,P$4-Input!$F$40),'Results-Unit'!$R$66)*P$8 -> 0 | ... CN32: =if(CN5<13,sumifs('Results-Unit'!$66:$66,'Results-Unit'!$56:$56,CN$4-Input!$F$40),'Results-Unit'!$R$66)*CN$8 -> -10720.765
B33: 2.3. | C33: ='Results-Unit'!C77 -> Other marketing and advertising expenses | E33: =IFERROR(F33/(CF!$F$30+$F$38+$F$49+$F$57+$F$35),0) -> 0 | F33: =SUM(I33:CN33) -> 0 | G33: $ | I33: =if(I5<13,sumifs('Results-Unit'!$77:$77,'Results-Unit'!$56:$56,I$4-Input!$F$40),'Results-Unit'!$R$77)*I$8 -> 0 | J33: =if(J5<13,sumifs('Results-Unit'!$77:$77,'Results-Unit'!$56:$56,J$4-Input!$F$40),'Results-Unit'!$R$77)*J$8 -> 0 | K33: =if(K5<13,sumifs('Results-Unit'!$77:$77,'Results-Unit'!$56:$56,K$4-Input!$F$40),'Results-Unit'!$R$77)*K$8 -> 0 | L33: =if(L5<13,sumifs('Results-Unit'!$77:$77,'Results-Unit'!$56:$56,L$4-Input!$F$40),'Results-Unit'!$R$77)*L$8 -> 0 | M33: =if(M5<13,sumifs('Results-Unit'!$77:$77,'Results-Unit'!$56:$56,M$4-Input!$F$40),'Results-Unit'!$R$77)*M$8 -> 0 | N33: =if(N5<13,sumifs('Results-Unit'!$77:$77,'Results-Unit'!$56:$56,N$4-Input!$F$40),'Results-Unit'!$R$77)*N$8 -> 0 | O33: =if(O5<13,sumifs('Results-Unit'!$77:$77,'Results-Unit'!$56:$56,O$4-Input!$F$40),'Results-Unit'!$R$77)*O$8 -> 0 | P33: =if(P5<13,sumifs('Results-Unit'!$77:$77,'Results-Unit'!$56:$56,P$4-Input!$F$40),'Results-Unit'!$R$77)*P$8 -> 0 | ... CN33: =if(CN5<13,sumifs('Results-Unit'!$77:$77,'Results-Unit'!$56:$56,CN$4-Input!$F$40),'Results-Unit'!$R$77)*CN$8 -> 0
B35: 3. | C35: Payroll — admin and others | E35: =IFERROR(F35/(CF!$F$30+$F$38+$F$49+$F$57+$F$35),0) -> 0.31450804 | F35: =SUM(I35:CN35) -> -1030163.5 | G35: $ | I35: =I37+I36 -> -9500 | J35: =J37+J36 -> -9500 | K35: =K37+K36 -> -9500 | L35: =L37+L36 -> -9500 | M35: =M37+M36 -> -9500 | N35: =N37+N36 -> -10600 | O35: =O37+O36 -> -10600 | P35: =P37+P36 -> -10600 | ... CN35: =CN37+CN36 -> -14205.014
B36: 3.1. | C36: Salary (Gross) | E36: =IFERROR(F36/(CF!$F$30+$F$38+$F$49+$F$57+$F$35),0) -> 0.31450804 | F36: =SUM(I36:CN36) -> -1030163.5 | G36: $ | I36: =Other!I73 -> -9500 | J36: =Other!J73 -> -9500 | K36: =Other!K73 -> -9500 | L36: =Other!L73 -> -9500 | M36: =Other!M73 -> -9500 | N36: =Other!N73 -> -10600 | O36: =Other!O73 -> -10600 | P36: =Other!P73 -> -10600 | ... CN36: =Other!CN73 -> -14205.014
B37: 3.2. | C37: =Input!C116 -> Additional taxes and insurance contributions for employees | E37: =IFERROR(F37/(CF!$F$30+$F$38+$F$49+$F$57+$F$35),0) -> 0 | F37: =SUM(I37:CN37) -> 0 | G37: $ | I37: =Other!I86 -> 0 | J37: =Other!J86 -> 0 | K37: =Other!K86 -> 0 | L37: =Other!L86 -> 0 | M37: =Other!M86 -> 0 | N37: =Other!N86 -> 0 | O37: =Other!O86 -> 0 | P37: =Other!P86 -> 0 | ... CN37: =Other!CN86 -> 0
B38: 4. | C38: =Input!C61 -> Fixed Expenses | E38: =IFERROR(F38/(CF!$F$30+$F$38+$F$49+$F$57+$F$35),0) -> 0.040269123 | F38: =SUM(I38:CN38) -> -131900.54 | G38: $ | I38: =SUM(I39:I48) -> -1350 | J38: =SUM(J39:J48) -> -1350 | K38: =SUM(K39:K48) -> -1350 | L38: =SUM(L39:L48) -> -1350 | M38: =SUM(M39:M48) -> -1350 | N38: =SUM(N39:N48) -> -1350 | O38: =SUM(O39:O48) -> -1350 | P38: =SUM(P39:P48) -> -1350 | ... CN38: =SUM(CN39:CN48) -> -1809.1291
B39: 4.1. | C39: =Input!C64 -> Servers | E39: =IFERROR(F39/(CF!$F$30+$F$38+$F$49+$F$57+$F$35),0) -> 0.035794776 | F39: =SUM(I39:CN39) -> -117244.92 | G39: $ | I39: =-IF(AND(I$1>=Input!$E64,I$1<=Input!$F64),Input!$D64,0)*I$8 -> -1200 | J39: =-IF(AND(J$1>=Input!$E64,J$1<=Input!$F64),Input!$D64,0)*J$8 -> -1200 | K39: =-IF(AND(K$1>=Input!$E64,K$1<=Input!$F64),Input!$D64,0)*K$8 -> -1200 | L39: =-IF(AND(L$1>=Input!$E64,L$1<=Input!$F64),Input!$D64,0)*L$8 -> -1200 | M39: =-IF(AND(M$1>=Input!$E64,M$1<=Input!$F64),Input!$D64,0)*M$8 -> -1200 | N39: =-IF(AND(N$1>=Input!$E64,N$1<=Input!$F64),Input!$D64,0)*N$8 -> -1200 | O39: =-IF(AND(O$1>=Input!$E64,O$1<=Input!$F64),Input!$D64,0)*O$8 -> -1200 | P39: =-IF(AND(P$1>=Input!$E64,P$1<=Input!$F64),Input!$D64,0)*P$8 -> -1200 | ... CN39: =-IF(AND(CN$1>=Input!$E64,CN$1<=Input!$F64),Input!$D64,0)*CN$8 -> -1608.1148
B40: 4.2. | C40: =Input!C65 -> App analytics service | E40: =IFERROR(F40/(CF!$F$30+$F$38+$F$49+$F$57+$F$35),0) -> 0.004474347 | F40: =SUM(I40:CN40) -> -14655.615 | G40: $ | I40: =-IF(AND(I$1>=Input!$E65,I$1<=Input!$F65),Input!$D65,0)*I$8 -> -150 | J40: =-IF(AND(J$1>=Input!$E65,J$1<=Input!$F65),Input!$D65,0)*J$8 -> -150 | K40: =-IF(AND(K$1>=Input!$E65,K$1<=Input!$F65),Input!$D65,0)*K$8 -> -150 | L40: =-IF(AND(L$1>=Input!$E65,L$1<=Input!$F65),Input!$D65,0)*L$8 -> -150 | M40: =-IF(AND(M$1>=Input!$E65,M$1<=Input!$F65),Input!$D65,0)*M$8 -> -150 | N40: =-IF(AND(N$1>=Input!$E65,N$1<=Input!$F65),Input!$D65,0)*N$8 -> -150 | O40: =-IF(AND(O$1>=Input!$E65,O$1<=Input!$F65),Input!$D65,0)*O$8 -> -150 | P40: =-IF(AND(P$1>=Input!$E65,P$1<=Input!$F65),Input!$D65,0)*P$8 -> -150 | ... CN40: =-IF(AND(CN$1>=Input!$E65,CN$1<=Input!$F65),Input!$D65,0)*CN$8 -> -201.01435
B41: 4.3. | C41: =Input!C66 | E41: =IFERROR(F41/(CF!$F$30+$F$38+$F$49+$F$57+$F$35),0) -> 0 | F41: =SUM(I41:CN41) -> 0 | G41: $ | I41: =-IF(AND(I$1>=Input!$E66,I$1<=Input!$F66),Input!$D66,0)*I$8 -> 0 | J41: =-IF(AND(J$1>=Input!$E66,J$1<=Input!$F66),Input!$D66,0)*J$8 -> 0 | K41: =-IF(AND(K$1>=Input!$E66,K$1<=Input!$F66),Input!$D66,0)*K$8 -> 0 | L41: =-IF(AND(L$1>=Input!$E66,L$1<=Input!$F66),Input!$D66,0)*L$8 -> 0 | M41: =-IF(AND(M$1>=Input!$E66,M$1<=Input!$F66),Input!$D66,0)*M$8 -> 0 | N41: =-IF(AND(N$1>=Input!$E66,N$1<=Input!$F66),Input!$D66,0)*N$8 -> 0 | O41: =-IF(AND(O$1>=Input!$E66,O$1<=Input!$F66),Input!$D66,0)*O$8 -> 0 | P41: =-IF(AND(P$1>=Input!$E66,P$1<=Input!$F66),Input!$D66,0)*P$8 -> 0 | ... CN41: =-IF(AND(CN$1>=Input!$E66,CN$1<=Input!$F66),Input!$D66,0)*CN$8 -> 0
B42: 4.4. | C42: =Input!C67 | E42: =IFERROR(F42/(CF!$F$30+$F$38+$F$49+$F$57+$F$35),0) -> 0 | F42: =SUM(I42:CN42) -> 0 | G42: $ | I42: =-IF(AND(I$1>=Input!$E67,I$1<=Input!$F67),Input!$D67,0)*I$8 -> 0 | J42: =-IF(AND(J$1>=Input!$E67,J$1<=Input!$F67),Input!$D67,0)*J$8 -> 0 | K42: =-IF(AND(K$1>=Input!$E67,K$1<=Input!$F67),Input!$D67,0)*K$8 -> 0 | L42: =-IF(AND(L$1>=Input!$E67,L$1<=Input!$F67),Input!$D67,0)*L$8 -> 0 | M42: =-IF(AND(M$1>=Input!$E67,M$1<=Input!$F67),Input!$D67,0)*M$8 -> 0 | N42: =-IF(AND(N$1>=Input!$E67,N$1<=Input!$F67),Input!$D67,0)*N$8 -> 0 | O42: =-IF(AND(O$1>=Input!$E67,O$1<=Input!$F67),Input!$D67,0)*O$8 -> 0 | P42: =-IF(AND(P$1>=Input!$E67,P$1<=Input!$F67),Input!$D67,0)*P$8 -> 0 | ... CN42: =-IF(AND(CN$1>=Input!$E67,CN$1<=Input!$F67),Input!$D67,0)*CN$8 -> 0
B43: 4.5. | C43: =Input!C68 | E43: =IFERROR(F43/(CF!$F$30+$F$38+$F$49+$F$57+$F$35),0) -> 0 | F43: =SUM(I43:CN43) -> 0 | G43: $ | I43: =-IF(AND(I$1>=Input!$E68,I$1<=Input!$F68),Input!$D68,0)*I$8 -> 0 | J43: =-IF(AND(J$1>=Input!$E68,J$1<=Input!$F68),Input!$D68,0)*J$8 -> 0 | K43: =-IF(AND(K$1>=Input!$E68,K$1<=Input!$F68),Input!$D68,0)*K$8 -> 0 | L43: =-IF(AND(L$1>=Input!$E68,L$1<=Input!$F68),Input!$D68,0)*L$8 -> 0 | M43: =-IF(AND(M$1>=Input!$E68,M$1<=Input!$F68),Input!$D68,0)*M$8 -> 0 | N43: =-IF(AND(N$1>=Input!$E68,N$1<=Input!$F68),Input!$D68,0)*N$8 -> 0 | O43: =-IF(AND(O$1>=Input!$E68,O$1<=Input!$F68),Input!$D68,0)*O$8 -> 0 | P43: =-IF(AND(P$1>=Input!$E68,P$1<=Input!$F68),Input!$D68,0)*P$8 -> 0 | ... CN43: =-IF(AND(CN$1>=Input!$E68,CN$1<=Input!$F68),Input!$D68,0)*CN$8 -> 0
B44: 4.6. | C44: =Input!C69 | E44: =IFERROR(F44/(CF!$F$30+$F$38+$F$49+$F$57+$F$35),0) -> 0 | F44: =SUM(I44:CN44) -> 0 | G44: $ | I44: =-IF(AND(I$1>=Input!$E69,I$1<=Input!$F69),Input!$D69,0)*I$8 -> 0 | J44: =-IF(AND(J$1>=Input!$E69,J$1<=Input!$F69),Input!$D69,0)*J$8 -> 0 | K44: =-IF(AND(K$1>=Input!$E69,K$1<=Input!$F69),Input!$D69,0)*K$8 -> 0 | L44: =-IF(AND(L$1>=Input!$E69,L$1<=Input!$F69),Input!$D69,0)*L$8 -> 0 | M44: =-IF(AND(M$1>=Input!$E69,M$1<=Input!$F69),Input!$D69,0)*M$8 -> 0 | N44: =-IF(AND(N$1>=Input!$E69,N$1<=Input!$F69),Input!$D69,0)*N$8 -> 0 | O44: =-IF(AND(O$1>=Input!$E69,O$1<=Input!$F69),Input!$D69,0)*O$8 -> 0 | P44: =-IF(AND(P$1>=Input!$E69,P$1<=Input!$F69),Input!$D69,0)*P$8 -> 0 | ... CN44: =-IF(AND(CN$1>=Input!$E69,CN$1<=Input!$F69),Input!$D69,0)*CN$8 -> 0
B45: 4.7. | C45: =Input!C70 | E45: =IFERROR(F45/(CF!$F$30+$F$38+$F$49+$F$57+$F$35),0) -> 0 | F45: =SUM(I45:CN45) -> 0 | G45: $ | I45: =-IF(AND(I$1>=Input!$E70,I$1<=Input!$F70),Input!$D70,0)*I$8 -> 0 | J45: =-IF(AND(J$1>=Input!$E70,J$1<=Input!$F70),Input!$D70,0)*J$8 -> 0 | K45: =-IF(AND(K$1>=Input!$E70,K$1<=Input!$F70),Input!$D70,0)*K$8 -> 0 | L45: =-IF(AND(L$1>=Input!$E70,L$1<=Input!$F70),Input!$D70,0)*L$8 -> 0 | M45: =-IF(AND(M$1>=Input!$E70,M$1<=Input!$F70),Input!$D70,0)*M$8 -> 0 | N45: =-IF(AND(N$1>=Input!$E70,N$1<=Input!$F70),Input!$D70,0)*N$8 -> 0 | O45: =-IF(AND(O$1>=Input!$E70,O$1<=Input!$F70),Input!$D70,0)*O$8 -> 0 | P45: =-IF(AND(P$1>=Input!$E70,P$1<=Input!$F70),Input!$D70,0)*P$8 -> 0 | ... CN45: =-IF(AND(CN$1>=Input!$E70,CN$1<=Input!$F70),Input!$D70,0)*CN$8 -> 0
B46: 4.8. | C46: =Input!C71 | E46: =IFERROR(F46/(CF!$F$30+$F$38+$F$49+$F$57+$F$35),0) -> 0 | F46: =SUM(I46:CN46) -> 0 | G46: $ | I46: =-IF(AND(I$1>=Input!$E71,I$1<=Input!$F71),Input!$D71,0)*I$8 -> 0 | J46: =-IF(AND(J$1>=Input!$E71,J$1<=Input!$F71),Input!$D71,0)*J$8 -> 0 | K46: =-IF(AND(K$1>=Input!$E71,K$1<=Input!$F71),Input!$D71,0)*K$8 -> 0 | L46: =-IF(AND(L$1>=Input!$E71,L$1<=Input!$F71),Input!$D71,0)*L$8 -> 0 | M46: =-IF(AND(M$1>=Input!$E71,M$1<=Input!$F71),Input!$D71,0)*M$8 -> 0 | N46: =-IF(AND(N$1>=Input!$E71,N$1<=Input!$F71),Input!$D71,0)*N$8 -> 0 | O46: =-IF(AND(O$1>=Input!$E71,O$1<=Input!$F71),Input!$D71,0)*O$8 -> 0 | P46: =-IF(AND(P$1>=Input!$E71,P$1<=Input!$F71),Input!$D71,0)*P$8 -> 0 | ... CN46: =-IF(AND(CN$1>=Input!$E71,CN$1<=Input!$F71),Input!$D71,0)*CN$8 -> 0
B47: 4.9. | C47: =Input!C72 | E47: =IFERROR(F47/(CF!$F$30+$F$38+$F$49+$F$57+$F$35),0) -> 0 | F47: =SUM(I47:CN47) -> 0 | G47: $ | I47: =-IF(AND(I$1>=Input!$E72,I$1<=Input!$F72),Input!$D72,0)*I$8 -> 0 | J47: =-IF(AND(J$1>=Input!$E72,J$1<=Input!$F72),Input!$D72,0)*J$8 -> 0 | K47: =-IF(AND(K$1>=Input!$E72,K$1<=Input!$F72),Input!$D72,0)*K$8 -> 0 | L47: =-IF(AND(L$1>=Input!$E72,L$1<=Input!$F72),Input!$D72,0)*L$8 -> 0 | M47: =-IF(AND(M$1>=Input!$E72,M$1<=Input!$F72),Input!$D72,0)*M$8 -> 0 | N47: =-IF(AND(N$1>=Input!$E72,N$1<=Input!$F72),Input!$D72,0)*N$8 -> 0 | O47: =-IF(AND(O$1>=Input!$E72,O$1<=Input!$F72),Input!$D72,0)*O$8 -> 0 | P47: =-IF(AND(P$1>=Input!$E72,P$1<=Input!$F72),Input!$D72,0)*P$8 -> 0 | ... CN47: =-IF(AND(CN$1>=Input!$E72,CN$1<=Input!$F72),Input!$D72,0)*CN$8 -> 0
B48: 4.8. | C48: =Input!C73 | E48: =IFERROR(F48/(CF!$F$30+$F$38+$F$49+$F$57+$F$35),0) -> 0 | F48: =SUM(I48:CN48) -> 0 | G48: $ | I48: =-IF(AND(I$1>=Input!$E73,I$1<=Input!$F73),Input!$D73,0)*I$8 -> 0 | J48: =-IF(AND(J$1>=Input!$E73,J$1<=Input!$F73),Input!$D73,0)*J$8 -> 0 | K48: =-IF(AND(K$1>=Input!$E73,K$1<=Input!$F73),Input!$D73,0)*K$8 -> 0 | L48: =-IF(AND(L$1>=Input!$E73,L$1<=Input!$F73),Input!$D73,0)*L$8 -> 0 | M48: =-IF(AND(M$1>=Input!$E73,M$1<=Input!$F73),Input!$D73,0)*M$8 -> 0 | N48: =-IF(AND(N$1>=Input!$E73,N$1<=Input!$F73),Input!$D73,0)*N$8 -> 0 | O48: =-IF(AND(O$1>=Input!$E73,O$1<=Input!$F73),Input!$D73,0)*O$8 -> 0 | P48: =-IF(AND(P$1>=Input!$E73,P$1<=Input!$F73),Input!$D73,0)*P$8 -> 0 | ... CN48: =-IF(AND(CN$1>=Input!$E73,CN$1<=Input!$F73),Input!$D73,0)*CN$8 -> 0
B49: 5. | C49: =Input!C77 -> Other Variable Expenses | E49: =IFERROR(F49/(CF!$F$30+$F$38+$F$49+$F$57+$F$35),0) -> 0.0750721 | F49: =SUM(I49:CN49) -> -245896.84 | G49: $ | I49: =SUM(I50:I52,I53:I56) -> 0 | J49: =SUM(J50:J52,J53:J56) -> 0 | K49: =SUM(K50:K52,K53:K56) -> 0 | L49: =SUM(L50:L52,L53:L56) -> 0 | M49: =SUM(M50:M52,M53:M56) -> 0 | N49: =SUM(N50:N52,N53:N56) -> 0 | O49: =SUM(O50:O52,O53:O56) -> 0 | P49: =SUM(P50:P52,P53:P56) -> 0 | ... CN49: =SUM(CN50:CN52,CN53:CN56) -> -3621.3049
B50: 5.1. | C50: =Input!C80 -> Stores Commission | E50: =IFERROR(F50/(CF!$F$30+$F$38+$F$49+$F$57+$F$35),0) -> 0 | F50: =SUM(I50:CN50) -> 0 | G50: $ | I50: =CHOOSE(Input!$G80,-I$27*Input!$D80,-Input!$D80*I$2) -> 0 | J50: =CHOOSE(Input!$G80,-J$27*Input!$D80,-Input!$D80*J$2) -> 0 | K50: =CHOOSE(Input!$G80,-K$27*Input!$D80,-Input!$D80*K$2) -> 0 | L50: =CHOOSE(Input!$G80,-L$27*Input!$D80,-Input!$D80*L$2) -> 0 | M50: =CHOOSE(Input!$G80,-M$27*Input!$D80,-Input!$D80*M$2) -> 0 | N50: =CHOOSE(Input!$G80,-N$27*Input!$D80,-Input!$D80*N$2) -> 0 | O50: =CHOOSE(Input!$G80,-O$27*Input!$D80,-Input!$D80*O$2) -> 0 | P50: =CHOOSE(Input!$G80,-P$27*Input!$D80,-Input!$D80*P$2) -> 0 | ... CN50: =CHOOSE(Input!$G80,-CN$27*Input!$D80,-Input!$D80*CN$2) -> 0
...

Sheet PL
A1: =BS!A1 -> Ok | B1: =CF!B1 -> № | C1: =CF!C1 -> Name | E1: =CF!E1 -> Share | F1: =CF!F1 -> Total | G1: =CF!G1 -> Unit | I1: =CF!I1 -> 46023 | J1: =CF!J1 -> 46054 | K1: =CF!K1 -> 46082 | L1: =CF!L1 -> 46113 | M1: =CF!M1 -> 46143 | N1: =CF!N1 -> 46174 | O1: =CF!O1 -> 46204 | P1: =CF!P1 -> 46235 | ... CN1: =CF!CN1 -> 48549
C2: =CF!C2 -> Sales volume, MAU | I2: =CF!I2 -> 0 | J2: =CF!J2 -> 0 | K2: =CF!K2 -> 0 | L2: =CF!L2 -> 0 | M2: =CF!M2 -> 0 | N2: =CF!N2 -> 0 | O2: =CF!O2 -> 0 | P2: =CF!P2 -> 0 | ... CN2: =CF!CN2 -> 229.33333
C3: =CF!C3 -> Year | I3: =CF!I3 -> 2026 | J3: =CF!J3 -> 2026 | K3: =CF!K3 -> 2026 | L3: =CF!L3 -> 2026 | M3: =CF!M3 -> 2026 | N3: =CF!N3 -> 2026 | O3: =CF!O3 -> 2026 | P3: =CF!P3 -> 2026 | ... CN3: =CF!CN3 -> 2032
C4: =CF!C4 -> Month | I4: =CF!I4 -> 1 | J4: =CF!J4 -> 2 | K4: =CF!K4 -> 3 | L4: =CF!L4 -> 4 | M4: =CF!M4 -> 5 | N4: =CF!N4 -> 6 | O4: =CF!O4 -> 7 | P4: =CF!P4 -> 8 | ... CN4: =CF!CN4 -> 12
C5: =CF!C5 -> Serial number of the period | I5: =CF!I5 -> 1 | J5: =CF!J5 -> 2 | K5: =CF!K5 -> 3 | L5: =CF!L5 -> 4 | M5: =CF!M5 -> 5 | N5: =CF!N5 -> 6 | O5: =CF!O5 -> 7 | P5: =CF!P5 -> 8 | ... CN5: =CF!CN5 -> 84
C6: =CF!C6 -> Indexation of production prices | I6: =CF!I6 -> 1 | J6: =CF!J6 -> 1 | K6: =CF!K6 -> 1 | L6: =CF!L6 -> 1 | M6: =CF!M6 -> 1 | N6: =CF!N6 -> 1 | O6: =CF!O6 -> 1 | P6: =CF!P6 -> 1 | ... CN6: =CF!CN6 -> 1.3400956
C7: =CF!C7 -> Payroll indexation | I7: =CF!I7 -> 1 | J7: =CF!J7 -> 1 | K7: =CF!K7 -> 1 | L7: =CF!L7 -> 1 | M7: =CF!M7 -> 1 | N7: =CF!N7 -> 1 | O7: =CF!O7 -> 1 | P7: =CF!P7 -> 1 | ... CN7: =CF!CN7 -> 1.3400956
C8: =CF!C8 -> Indexation of other expenses | I8: =CF!I8 -> 1 | J8: =CF!J8 -> 1 | K8: =CF!K8 -> 1 | L8: =CF!L8 -> 1 | M8: =CF!M8 -> 1 | N8: =CF!N8 -> 1 | O8: =CF!O8 -> 1 | P8: =CF!P8 -> 1 | ... CN8: =CF!CN8 -> 1.3400956
C9: =CF!C9 -> Sales price indexation | I9: =CF!I9 -> 1 | J9: =CF!J9 -> 1 | K9: =CF!K9 -> 1 | L9: =CF!L9 -> 1 | M9: =CF!M9 -> 1 | N9: =CF!N9 -> 1 | O9: =CF!O9 -> 1 | P9: =CF!P9 -> 1 | ... CN9: =CF!CN9 -> 1.3400956
C13: Profit and Loss Statement (PL)
B15: 1. | C15: Revenue | E15: =IFERROR(F15/$F$15,0) -> 1 | F15: =SUM(I15:CN15) -> 7487545.6 | G15: $ | I15: =SUM(I16) -> 0 | J15: =SUM(J16) -> 0 | K15: =SUM(K16) -> 0 | L15: =SUM(L16) -> 0 | M15: =SUM(M16) -> 0 | N15: =SUM(N16) -> 0 | O15: =SUM(O16) -> 0 | P15: =SUM(P16) -> 0 | ... CN15: =SUM(CN16) -> 117077.56
B16: 1.1. | C16: =CF!C28 -> Income — StepUP | E16: =IFERROR(F16/$F$15,0) -> 1 | F16: =SUM(I16:CN16) -> 7487545.6 | G16: $ | I16: =CF!I28/(1+Input!$D$115) -> 0 | J16: =CF!J28/(1+Input!$D$115) -> 0 | K16: =CF!K28/(1+Input!$D$115) -> 0 | L16: =CF!L28/(1+Input!$D$115) -> 0 | M16: =CF!M28/(1+Input!$D$115) -> 0 | N16: =CF!N28/(1+Input!$D$115) -> 0 | O16: =CF!O28/(1+Input!$D$115) -> 0 | P16: =CF!P28/(1+Input!$D$115) -> 0 | ... CN16: =CF!CN28/(1+Input!$D$115) -> 117077.56
B17: 2. | C17: =CF!C30 -> Direct costs (marketing and sales) | E17: =IFERROR(F17/($F$17+$F$23+$F$26+$F$37),0) -> 0.43291251 | F17: =SUM(I17:CN17) -> -1061098.4 | G17: $ | I17: =SUM(I18:I20) -> 0 | J17: =SUM(J18:J20) -> 0 | K17: =SUM(K18:K20) -> 0 | L17: =SUM(L18:L20) -> 0 | M17: =SUM(M18:M20) -> 0 | N17: =SUM(N18:N20) -> 0 | O17: =SUM(O18:O20) -> 0 | P17: =SUM(P18:P20) -> 0 | ... CN17: =SUM(CN18:CN20) -> -16591.66
B18: 2.1. | C18: =CF!C31 -> Advertising and marketing expenses | E18: =IFERROR(F18/($F$17+$F$23+$F$26+$F$37),0) -> 0.16650481 | F18: =SUM(I18:CN18) -> -408114.77 | G18: $ | I18: =CF!I31/(1+Input!$D$115) -> 0 | J18: =CF!J31/(1+Input!$D$115) -> 0 | K18: =CF!K31/(1+Input!$D$115) -> 0 | L18: =CF!L31/(1+Input!$D$115) -> 0 | M18: =CF!M31/(1+Input!$D$115) -> 0 | N18: =CF!N31/(1+Input!$D$115) -> 0 | O18: =CF!O31/(1+Input!$D$115) -> 0 | P18: =CF!P31/(1+Input!$D$115) -> 0 | ... CN18: =CF!CN31/(1+Input!$D$115) -> -6381.4078
B19: 2.2. | C19: =CF!C32 -> Salary (marketing and sales) | E19: =IFERROR(F19/($F$17+$F$23+$F$26+$F$37),0) -> 0.2664077 | F19: =SUM(I19:CN19) -> -652983.63 | G19: $ | I19: =CF!I32/(1+Input!$D$115) -> 0 | J19: =CF!J32/(1+Input!$D$115) -> 0 | K19: =CF!K32/(1+Input!$D$115) -> 0 | L19: =CF!L32/(1+Input!$D$115) -> 0 | M19: =CF!M32/(1+Input!$D$115) -> 0 | N19: =CF!N32/(1+Input!$D$115) -> 0 | O19: =CF!O32/(1+Input!$D$115) -> 0 | P19: =CF!P32/(1+Input!$D$115) -> 0 | ... CN19: =CF!CN32/(1+Input!$D$115) -> -10210.253
B20: 2.3. | C20: =CF!C33 -> Other marketing and advertising expenses | E20: =IFERROR(F20/($F$17+$F$23+$F$26+$F$37),0) -> 0 | F20: =SUM(I20:CN20) -> 0 | G20: $ | I20: =CF!I33/(1+Input!$D$115) -> 0 | J20: =CF!J33/(1+Input!$D$115) -> 0 | K20: =CF!K33/(1+Input!$D$115) -> 0 | L20: =CF!L33/(1+Input!$D$115) -> 0 | M20: =CF!M33/(1+Input!$D$115) -> 0 | N20: =CF!N33/(1+Input!$D$115) -> 0 | O20: =CF!O33/(1+Input!$D$115) -> 0 | P20: =CF!P33/(1+Input!$D$115) -> 0 | ... CN20: =CF!CN33/(1+Input!$D$115) -> 0
C21: Gross profit | F21: =SUM(I21:CN21) -> 6426447.2 | G21: $ | I21: =I17+I15 -> 0 | J21: =J17+J15 -> 0 | K21: =K17+K15 -> 0 | L21: =L17+L15 -> 0 | M21: =M17+M15 -> 0 | N21: =N17+N15 -> 0 | O21: =O17+O15 -> 0 | P21: =P17+P15 -> 0 | ... CN21: =CN17+CN15 -> 100485.9
C22: Return on sales | F22: =IFERROR(F21/F15,0) -> 0.85828488 | G22: % | I22: =IFERROR(I21/I15,0) -> 0 | J22: =IFERROR(J21/J15,0) -> 0 | K22: =IFERROR(K21/K15,0) -> 0 | L22: =IFERROR(L21/L15,0) -> 0 | M22: =IFERROR(M21/M15,0) -> 0 | N22: =IFERROR(N21/N15,0) -> 0 | O22: =IFERROR(O21/O15,0) -> 0 | P22: =IFERROR(P21/P15,0) -> 0 | ... CN22: =IFERROR(CN21/CN15,0) -> 0.85828488
B23: 3. | C23: =CF!C35 -> Payroll — admin and others | E23: =IFERROR(F23/($F$17+$F$23+$F$26+$F$37),0) -> 0.42029152 | F23: =SUM(I23:CN23) -> -1030163.5 | G23: $ | I23: =I25+I24 -> -9500 | J23: =J25+J24 -> -9500 | K23: =K25+K24 -> -9500 | L23: =L25+L24 -> -9500 | M23: =M25+M24 -> -9500 | N23: =N25+N24 -> -10600 | O23: =O25+O24 -> -10600 | P23: =P25+P24 -> -10600 | ... CN23: =CN25+CN24 -> -14205.014
B24: 3.1. | C24: =CF!C36 -> Salary (Gross) | E24: =IFERROR(F24/($F$17+$F$23+$F$26+$F$37),0) -> 0.42029152 | F24: =SUM(I24:CN24) -> -1030163.5 | G24: $ | I24: =CF!I36 -> -9500 | J24: =CF!J36 -> -9500 | K24: =CF!K36 -> -9500 | L24: =CF!L36 -> -9500 | M24: =CF!M36 -> -9500 | N24: =CF!N36 -> -10600 | O24: =CF!O36 -> -10600 | P24: =CF!P36 -> -10600 | ... CN24: =CF!CN36 -> -14205.014
B25: 3.2. | C25: =CF!C37 -> Additional taxes and insurance contributions for employees | E25: =IFERROR(F25/($F$17+$F$23+$F$26+$F$37),0) -> 0 | F25: =SUM(I25:CN25) -> 0 | G25: $ | I25: =CF!I37 -> 0 | J25: =CF!J37 -> 0 | K25: =CF!K37 -> 0 | L25: =CF!L37 -> 0 | M25: =CF!M37 -> 0 | N25: =CF!N37 -> 0 | O25: =CF!O37 -> 0 | P25: =CF!P37 -> 0 | ... CN25: =CF!CN37 -> 0
B26: 4. | C26: =CF!C38 -> Fixed Expenses | E26: =IFERROR(F26/($F$17+$F$23+$F$26+$F$37),0) -> 0.051250929 | F26: =SUM(I26:CN26) -> -125619.56 | G26: $ | I26: =SUM(I27:I36) -> -1285.7143 | J26: =SUM(J27:J36) -> -1285.7143 | K26: =SUM(K27:K36) -> -1285.7143 | L26: =SUM(L27:L36) -> -1285.7143 | M26: =SUM(M27:M36) -> -1285.7143 | N26: =SUM(N27:N36) -> -1285.7143 | O26: =SUM(O27:O36) -> -1285.7143 | P26: =SUM(P27:P36) -> -1285.7143 | ... CN26: =SUM(CN27:CN36) -> -1722.9801
B27: 4.1. | C27: =CF!C39 -> Servers | E27: =IFERROR(F27/($F$17+$F$23+$F$26+$F$37),0) -> 0.045556382 | F27: =SUM(I27:CN27) -> -111661.83 | G27: $ | I27: =CF!I39/(1+Input!$D$115) -> -1142.8571 | J27: =CF!J39/(1+Input!$D$115) -> -1142.8571 | K27: =CF!K39/(1+Input!$D$115) -> -1142.8571 | L27: =CF!L39/(1+Input!$D$115) -> -1142.8571 | M27: =CF!M39/(1+Input!$D$115) -> -1142.8571 | N27: =CF!N39/(1+Input!$D$115) -> -1142.8571 | O27: =CF!O39/(1+Input!$D$115) -> -1142.8571 | P27: =CF!P39/(1+Input!$D$115) -> -1142.8571 | ... CN27: =CF!CN39/(1+Input!$D$115) -> -1531.5379
B28: 4.2. | C28: =CF!C40 -> App analytics service | E28: =IFERROR(F28/($F$17+$F$23+$F$26+$F$37),0) -> 0.0056945477 | F28: =SUM(I28:CN28) -> -13957.729 | G28: $ | I28: =CF!I40/(1+Input!$D$115) -> -142.85714 | J28: =CF!J40/(1+Input!$D$115) -> -142.85714 | K28: =CF!K40/(1+Input!$D$115) -> -142.85714 | L28: =CF!L40/(1+Input!$D$115) -> -142.85714 | M28: =CF!M40/(1+Input!$D$115) -> -142.85714 | N28: =CF!N40/(1+Input!$D$115) -> -142.85714 | O28: =CF!O40/(1+Input!$D$115) -> -142.85714 | P28: =CF!P40/(1+Input!$D$115) -> -142.85714 | ... CN28: =CF!CN40/(1+Input!$D$115) -> -191.44223
B29: 4.3. | C29: =CF!C41 | E29: =IFERROR(F29/($F$17+$F$23+$F$26+$F$37),0) -> 0 | F29: =SUM(I29:CN29) -> 0 | G29: $ | I29: =CF!I41/(1+Input!$D$115) -> 0 | J29: =CF!J41/(1+Input!$D$115) -> 0 | K29: =CF!K41/(1+Input!$D$115) -> 0 | L29: =CF!L41/(1+Input!$D$115) -> 0 | M29: =CF!M41/(1+Input!$D$115) -> 0 | N29: =CF!N41/(1+Input!$D$115) -> 0 | O29: =CF!O41/(1+Input!$D$115) -> 0 | P29: =CF!P41/(1+Input!$D$115) -> 0 | ... CN29: =CF!CN41/(1+Input!$D$115) -> 0
B30: 4.4. | C30: =CF!C42 | E30: =IFERROR(F30/($F$17+$F$23+$F$26+$F$37),0) -> 0 | F30: =SUM(I30:CN30) -> 0 | G30: $ | I30: =CF!I42/(1+Input!$D$115) -> 0 | J30: =CF!J42/(1+Input!$D$115) -> 0 | K30: =CF!K42/(1+Input!$D$115) -> 0 | L30: =CF!L42/(1+Input!$D$115) -> 0 | M30: =CF!M42/(1+Input!$D$115) -> 0 | N30: =CF!N42/(1+Input!$D$115) -> 0 | O30: =CF!O42/(1+Input!$D$115) -> 0 | P30: =CF!P42/(1+Input!$D$115) -> 0 | ... CN30: =CF!CN42/(1+Input!$D$115) -> 0
B31: 4.5. | C31: =CF!C43 | E31: =IFERROR(F31/($F$17+$F$23+$F$26+$F$37),0) -> 0 | F31: =SUM(I31:CN31) -> 0 | G31: $ | I31: =CF!I43/(1+Input!$D$115) -> 0 | J31: =CF!J43/(1+Input!$D$115) -> 0 | K31: =CF!K43/(1+Input!$D$115) -> 0 | L31: =CF!L43/(1+Input!$D$115) -> 0 | M31: =CF!M43/(1+Input!$D$115) -> 0 | N31: =CF!N43/(1+Input!$D$115) -> 0 | O31: =CF!O43/(1+Input!$D$115) -> 0 | P31: =CF!P43/(1+Input!$D$115) -> 0 | ... CN31: =CF!CN43/(1+Input!$D$115) -> 0
B32: 4.6. | C32: =CF!C44 | E32: =IFERROR(F32/($F$17+$F$23+$F$26+$F$37),0) -> 0 | F32: =SUM(I32:CN32) -> 0 | G32: $ | I32: =CF!I44/(1+Input!$D$115) -> 0 | J32: =CF!J44/(1+Input!$D$115) -> 0 | K32: =CF!K44/(1+Input!$D$115) -> 0 | L32: =CF!L44/(1+Input!$D$115) -> 0 | M32: =CF!M44/(1+Input!$D$115) -> 0 | N32: =CF!N44/(1+Input!$D$115) -> 0 | O32: =CF!O44/(1+Input!$D$115) -> 0 | P32: =CF!P44/(1+Input!$D$115) -> 0 | ... CN32: =CF!CN44/(1+Input!$D$115) -> 0
B33: 4.7. | C33: =CF!C45 | E33: =IFERROR(F33/($F$17+$F$23+$F$26+$F$37),0) -> 0 | F33: =SUM(I33:CN33) -> 0 | G33: $ | I33: =CF!I45/(1+Input!$D$115) -> 0 | J33: =CF!J45/(1+Input!$D$115) -> 0 | K33: =CF!K45/(1+Input!$D$115) -> 0 | L33: =CF!L45/(1+Input!$D$115) -> 0 | M33: =CF!M45/(1+Input!$D$115) -> 0 | N33: =CF!N45/(1+Input!$D$115) -> 0 | O33: =CF!O45/(1+Input!$D$115) -> 0 | P33: =CF!P45/(1+Input!$D$115) -> 0 | ... CN33: =CF!CN45/(1+Input!$D$115) -> 0
